Workbook

Sheet Cover
B3: #VALUE!
D4: Shree Cement Ltd.
D7: Financial Modelling and Valuation Analysis
C10: Company : Shree Cement Ltd. | H10: xxxx | I10: Inputs / Assumptions
C11: Ticker : NSE: SHREECEM, BSE: 500387 | H11: xxxx | I11: Formulae
C12: Sector : Basic Materials | H12: xxxx | I12: Linking/ Reference cell
C13: Industry : Construction Materials
C14: Sub-Industry: Cement & Construction Materials
C15: Analyst : Manish Rathour
E17: INDEX
D19: Assumptions
D20: Revenue Growth Scenarios
D21: Historical Information
D22: Comps Data
D23: Market Returns
D24: WACC
D25: Beta
D26: Schedules
D27: Financial Statements
D28: DCF Valuation
D29: Sensitivity Analysis
D30: Comps Valuation
... D32: Valuation Summary- Football Field Analysis

Sheet Assumptions->

Sheet Assumptions
A1: =Historical!A1 -> Shree Cement Ltd.
A2: Assumptions
D4: Company Description | E4: =Cover!D4 -> Shree Cement Ltd.
D5: ISIN Code | E5: INE071E01023
D6: Sector Name | E6: Basic Materials
D7: Industry | E7: Construction Materials
D8: Exchange Name | E8: NSE: SHREECEM, BSE: 500387
D9: Website | E9: https://www.shreecement.com/
D10: Company Description | E10: Shree Cement Limited, incorporated in 1979 and headquartered in Kolkata, is India's third-largest cement manufacturer by capacity. Among India's top four cement companies- Shree Cement is aggressively expanding capacity, targeting 80 MTPA by FY28 from its current 56.4 MTPA, commanding approximately 8-9% of India's total installed cement capacity. Operating under marquee brands- Bangur Cement, Rockstrong, and Shree Ultra, it dominates North and East Indian markets. The company also operates 888.6 MW of captive power, giving it a structural cost advantage over peers.
D11: Current Market Price | E11: ='Comps Data'!F5 -> 24890
D14: Scenario
D15: Base Case | F15: 1
D18: Company Data
D19: Particulars | G19: Amount
D20: No of Outstanding shares | E20: Unit | G20: 36081421
D21: Face Value per share | E21: Rs. | G21: 10
D22: Current Market Price | E22: Rs. | G22: =E11 -> 24890
D23: Market Capitalisation | E23: Rs. in Cr. | G23: ='Comps Valuation'!J17 -> 89806.657
D26: Assumptions
D27: Perpetual Growth rate | E27: % | G27: =DCF!E11 -> 0.04
D28: 10 year Bond yield rate | E28: % | G28: ='Market Returns'!I11 -> 0.06929
D29: Tax Rate | E29: % | G29: ='Comps Valuation'!Q17 -> 0.246511
D32: Particular | E32: Assumptions
D33: Revenue Buildup | E33: Although the other companies such as JK Cement, Ambuja Cement etc are expecting double digit growth, I have used conservative approach and followed the Management guidance. As per Q3 FY26 Concall, the Management expects the industry demand to be around 7.5-8.0%, Shree Cement expects to grow at least in line with the industry, Hence i have assumed the Revenue growth rate of 7.5% for FY26 as the Anchor to forecast throughout the forecast period, though historically Shree has outpaced it. A +2.5% premium was applied for the Bull Case (10%) to reflect accelerated capacity exansion which is projected in upcoming years, and a -2.5% haircut for the Bear Case (5%) to adjust for demand softness, pricing pressure, or execution delays.
E34: During Revenue Growth Scenario, Tapering of 7.5% is taken assuming 4% of Growth rate in long run after the forecast period ends in base case Scenario.
D35: Cost Buildup | E35: COGS, Employee Salaries & Benefits, Freight & Forwarding Expenses, and Other SG&A Expenses are each modelled as a percentage of revenue, held constant at their respective historical average ratios derived from FY2021–FY2025 data. These cost heads are operationally linked to revenue and have shown stable trends historically, making the average % of revenue the most reliable forecast anchor.
E36: D&A is modelled as a % of opening PP&E, assumed +1% step-up in every 3 years starting from FY26 - keeping FY25 as anchor, which is reflecting Shree Cement's aggressive capacity expansion and deepening asset base.
E37: Interest is computed as a % of opening debt balance, assumed to grow at the historical average rate, This approach reflects a stable borrowing cost assumption absent any guidance on refinancing or new debt issuances.
E38: Other Income is modelled as a % of revenue, assumed to grow at the historical average, keeping it constant throughout the forecast period.
E39: Taxes are modelled as a % of EBT as FY2025 taken as base, with a +0.5% step-up in every two years, converging gradually toward the statutory rate of 30%.
D40: Balance Sheet Items | E40: I have averaged historical Capex over FY2021–FY2025 and assumed it to grow at average growth rate of historical years while stepping up by 0.5% per year through the forecast period. The adjusted Capex is allocated to PP&E in proportion to the asset composition observed in FY2025 (the latest audited year).
E41: PP&E is forecasted using PP&E Schedule, Opening PP&E for each year is sourced from the closing balance of the prior year. Capex additions and depreciation charges are computed from the Depreciation Schedule in the Working Schedules tab.
E42: Bank Deposits, Current investments, Other Current Assets, Financial Assets, Other Non-Current Assets, Other Current & Non-Current Liabilities are held constant at their FY2025 audited levels throughout the forecast period As no company disclosures, management guidance, or industry data were available to support a directional assumption.
E43: Intagibles in Non-current assets and Non controlling Interest are straightlined throughout the forecast period as per FY25
E44: Dividend payout is also assumed to grow at the average historical growth rate (18.42%), keeping it constant throughout the forecast period.
E45: Equity Share Capital is held constant at the FY2025 level of ₹36.1 Cr. throughout the forecast period. The company has not announced any plans for a rights issue, ESOP dilution, or buyback, and the face value remains unchanged. | Y45: -Shree cement, 'Q3 FY26 Concall Transcript
E46: Cash and Cash Equivalents serve as the balancing figure in the Balance Sheet for each forecast year. The closing cash balance is derived from the Cash Flow Statement (Operating + Investing + Financing cash flows), ensuring internal consistency across all three financial statements.
E47: DSO, DIO, and DPO are computed using a 365-day convention and assumed to grow at their respective historical average growth rates derived from FY2021–FY2025 data. These ratios are then used to back-calculate Trade Receivables, Inventory, and Trade Payables as a function of Revenue and COGS respectively in each forecast year.
E48: Debt is forecasted using Debt Schedule, Opening debt for each year is sourced from the closing balance of the previous year.
E49: No information is given regarding issuance or repayment of debt, hense the Issuance and repayment of debt is assumed to be Zero throughout the forecast period.
...

Sheet Revenue Scenarios
A1: =Historical!A1 -> Shree Cement Ltd. | H1: Forecasted Information
A2: Revenue Scenarios | H2: ='Financial Statements'!M2 -> 2026 | I2: ='Financial Statements'!N2 -> 2027 | J2: ='Financial Statements'!O2 -> 2028 | K2: ='Financial Statements'!P2 -> 2029 | L2: ='Financial Statements'!Q2 -> 2030 | M2: ='Financial Statements'!R2 -> 2031 | N2: ='Financial Statements'!S2 -> 2032 | O2: ='Financial Statements'!T2 -> 2033 | ... Q2: ='Financial Statements'!V2 -> 2035
U3: Particulars | V3: FY 2020-21 | W3: FY 2021-22 | X3: FY 2022-23 | Y3: FY 2023-24 | Z3: FY 2024-25
D4: Scenarios | E4: Growth % | U4: Total Revenue from Ops (₹ Cr) | V4: 13559.77 | W4: 15009.56 | X4: 17852.33 | Y4: 20403.8 | Z4: 19282.83
D5: Base Case | E5: 0.075 | H5: =E5 -> 0.075 | I5: =H5*(1-$E$8) -> 0.070125 | J5: =I5*(1-$E$8) -> 0.065566875 | K5: =J5*(1-$E$8) -> 0.061305028 | L5: =K5*(1-$E$8) -> 0.057320201 | M5: =L5*(1-$E$8) -> 0.053594388 | N5: =M5*(1-$E$8) -> 0.050110753 | O5: =N5*(1-$E$8) -> 0.046853554 | P5: =O5*(1-$E$8) -> 0.043808073 | Q5: =P5*(1-$E$8) -> 0.040960548 | U5: 1. Cement & Clinker
D6: Bear Case | E6: =E5-2.5% -> 0.05 | H6: =E6 -> 0.05 | I6: =H6*(1-$E$8) -> 0.04675 | J6: =I6*(1-$E$8) -> 0.04371125 | K6: =J6*(1-$E$8) -> 0.040870019 | L6: =K6*(1-$E$8) -> 0.038213468 | M6: =L6*(1-$E$8) -> 0.035729592 | N6: =M6*(1-$E$8) -> 0.033407169 | O6: =N6*(1-$E$8) -> 0.031235703 | P6: =O6*(1-$E$8) -> 0.029205382 | Q6: =P6*(1-$E$8) -> 0.027307032 | U6: - Revenue Contribution (₹ Cr) | V6: 13,017.67 | W6: 14073.93 | X6: 16516.36 | Y6: 18460.16 | Z6: 17854.51
D7: Bull Case | E7: =E5+2.5% -> 0.1 | H7: =E7 -> 0.1 | I7: =H7*(1-$E$8) -> 0.0935 | J7: =I7*(1-$E$8) -> 0.0874225 | K7: =J7*(1-$E$8) -> 0.081740038 | L7: =K7*(1-$E$8) -> 0.076426935 | M7: =L7*(1-$E$8) -> 0.071459184 | N7: =M7*(1-$E$8) -> 0.066814337 | O7: =N7*(1-$E$8) -> 0.062471405 | P7: =O7*(1-$E$8) -> 0.058410764 | Q7: =P7*(1-$E$8) -> 0.054614064 | U7: - Volume (Million Tonnes) | V7: 26.84 | W7: 27.74 | X7: 31.82 | Y7: 35.54 | Z7: 36.06
D8: Tapering | E8: 0.065 | U8: Contribution % | V8: =V6/V4 -> 0.96002145 | W8: =W6/W4 -> 0.9376644 | X8: =X6/X4 -> 0.92516551 | Y8: =Y6/Y4 -> 0.90474127 | Z8: =Z6/Z4 -> 0.92592789
U9: 2. Power Sales
U10: - Revenue Contribution (₹ Cr) | V10: 105.98 | W10: 399.82 | X10: 826.56 | Y10: 1611.99 | Z10: 1098.16
D11: Back to Cover | U11: - Volume | V11: Captive/Grid | W11: Captive/Grid | X11: Captive/Grid | Y11: Captive/Grid | Z11: Captive/Grid
U12: Contribution % | V12: =V10/V4 -> 0.0078157668 | W12: =W10/W4 -> 0.02663769 | X12: =X10/X4 -> 0.046299839 | Y12: =Y10/Y4 -> 0.079004401 | Z12: =Z10/Z4 -> 0.056950147
T13: 3. Others (Traded/Misc.)
T14: - Revenue Contribution (₹ Cr) | U14: 436.12 | V14: 535.81 | W14: 509.41 | X14: 331.65 | Y14: 330.16
U15: =U14/V4 -> 0.032162787 | V15: =V14/W4 -> 0.035697915 | W15: =W14/X4 -> 0.028534651 | X15: =X14/Y4 -> 0.016254325 | Y15: =Y14/Z4 -> 0.017121968

Sheet Input->

Sheet Historical
A1: =Cover!D4 -> Shree Cement Ltd.
A2: Historical Information (All figures in INR Cr. Unless stated otherwise) | H2: 2021 | I2: =H2+1 -> 2022 | J2: =I2+1 -> 2023 | K2: =J2+1 -> 2024 | L2: =K2+1 -> 2025
A4: PROFIT & LOSS STATEMENT
C5: REVENUE
D6: Revenue from Operations
D7: Gross Revenue from Operations | F7: ₹ in Cr | H7: 17034.22 | I7: 18763.91 | J7: 22396.54 | K7: 20403.8 | L7: 19282.83
D8: Less: GST/VAT recovered | H8: 3474.45 | I8: 3754.35 | J8: 4544.21 | K8: 0 | L8: 0
D9: Net Revenue from Operations | H9: =H7-H8 -> 13559.77 | I9: =I7-I8 -> 15009.56 | J9: =J7-J8 -> 17852.33 | K9: =K7-K8 -> 20403.8 | L9: =L7-L8 -> 19282.83
D10: Other Income | H10: 438.26 | I10: 545.89 | J10: 459.08 | K10: 598.12 | L10: 589.22
D11: Total Income | H11: =SUM(H9:H10) -> 13998.03 | I11: =SUM(I9:I10) -> 15555.45 | J11: =SUM(J9:J10) -> 18311.41 | K11: =SUM(K9:K10) -> 21001.92 | L11: =SUM(L9:L10) -> 19872.05
D12: EXPENSES
D13: Cost of Materials Consumed | H13: 976.37 | I13: 1129.89 | J13: 1417.72 | K13: 2014.99 | L13: 1940.1
D14: Purchases of Stock-in-Trade | H14: 43.66 | I14: 87.51 | J14: 90.04 | K14: 10.18 | L14: 18.79
D15: Changes in Inventories of Finished Goods, Stock-in-Trade and Work-in-Progress | H15: 49.6 | I15: -179.21 | J15: -75.32 | K15: -87.81 | L15: 49.07
D16: Employee Benefits Expenses | H16: 869.22 | I16: 913.46 | J16: 977.77 | K16: 1064.43 | L16: 1147.83
D17: Power and Fuel | H17: 2397.9 | I17: 3620.18 | J17: 6080.66 | K17: 6254.54 | L17: 5011.84
D18: Freight and Forwarding Expenses | H18: 2294.31 | I18: 2469.07 | J18: 2782.46 | K18: 3238.1 | L18: 3412.37
D19: Inter Unit Clinker Transfer | H19: 815.88 | I19: 829.89 | J19: 1001.17 | K19: 912.43 | L19: 972.39
D20: Finance Costs | H20: 251.29 | I20: 216.12 | J20: 262.87 | K20: 258.34 | L20: 204.96
D21: Depreciation and Amortisation Expenses | H21: 1262.34 | I21: 1145.88 | J21: 1660.67 | K21: 1897.32 | L21: 3006.78
D22: Other Expenses | H22: 2048.65 | I22: 2459.12 | J22: 2681.44 | K22: 2514.54 | L22: 2844.49
D23: Captive Consumption of Cement | H23: -15.27 | I23: -28.28 | J23: -63.11 | K23: -34.34 | L23: -48.08
D24: Total Expenses | H24: =SUM(H13:H23) -> 10993.95 | I24: =SUM(I13:I23) -> 12663.63 | J24: =SUM(J13:J23) -> 16816.37 | K24: =SUM(K13:K23) -> 18042.72 | L24: =SUM(L13:L23) -> 18560.54
D25: PROFIT BEFORE TAX | H25: =H11-H24 -> 3004.08 | I25: =I11-I24 -> 2891.82 | J25: =J11-J24 -> 1495.04 | K25: =K11-K24 -> 2959.2 | L25: =L11-L24 -> 1311.51
D26: Tax Expense:
D27: Current Tax | H27: 765.27 | I27: 547.93 | J27: 252.25 | K27: 511.94 | L27: 336.21
D28: Tax Expense Relating to Earlier Years (Net) | H28: -10.27 | I28: -104.53 | J28: -154.31 | K28: 0 | L28: -0.06
D29: Deferred Tax (Credit) / Charge | H29: -40.51 | I29: 111.81 | J29: 127.96 | K29: 51.1 | L29: -148.44
D30: Total Tax | H30: 714.49 | I30: 555.21 | J30: 225.9 | K30: 563.04 | L30: 187.71
D31: PROFIT FOR THE YEAR | H31: =H25-H30 -> 2289.59 | I31: =I25-I30 -> 2336.61 | J31: =J25-J30 -> 1269.14 | K31: =K25-K30 -> 2396.16 | L31: =L25-L30 -> 1123.8
A34: BALANCE SHEET
B35: ASSETS
C36: Non-Current Assets
D37: Property, Plant and Equipment | F37: =F7 -> ₹ in Cr | H37: 5714.5 | I37: 6724.19 | J37: 6793.74 | K37: 8834.95 | L37: 8548.17
D38: Capital Work-in-Progress | H38: 996.54 | I38: 1053.52 | J38: 2796.61 | K38: 1929.67 | L38: 3796.22
D39: Intangible Assets | H39: 60.25 | I39: 57.25 | J39: 74.67 | K39: 123.45 | L39: 93.24
D40: Right of Use Assets | H40: 441.5 | I40: 500.8 | J40: 612.46 | K40: 632.51 | L40: 673.31
D41: Financial Assets:
D42: i) Investments | H42: 4699.03 | I42: 5506.34 | J42: 5285.25 | K42: 2291.79 | L42: 1396.47
D43: ii) Loans | H43: 4.46 | I43: 4.35 | J43: 3.67 | K43: 3.41 | L43: 2.84
...

Sheet Comps Data
A1: =Historical!A1 -> Shree Cement Ltd.
A2: Comparable Companies's Financial Information
D4: Company | E4: Ticker | F4: Stock Price | G4: Weighted Avg. Shares Outstanding Dil | H4: Market Cap | I4: Total Debt | J4: Total Cash And Short Term Investments | K4: Total Revenues | L4: EBITDA | M4: Net Income | N4: Effective Tax Rate
D5: Shree Cement Limited | E5: SHREECEM | F5: 24890 | G5: 3.6081421 | H5: =F5*G5 -> 89806.657 | I5: 2218.2519 | J5: 7853.7527 | K5: 21100.185 | L5: 5699.4631 | M5: 1856.0239 | N5: 0.246511
D6: UltraTech Cement Limited | E6: ULTRACEMCO | F6: 11452 | G6: 29.434026 | H6: =F6*G6 -> 337078.47 | I6: 26113.01 | J6: 3811.6224 | K6: 88830.512 | L6: 16522.795 | M6: 7937.9277 | N6: 0.23731
D7: Ambuja Cements Limited | E7: 500425 | F7: 441.75 | G7: 246.78659 | H7: =F7*G7 -> 109017.98 | I7: 1315.9803 | J7: 474.83077 | K7: 40833.458 | L7: 6510.1913 | M7: 3826.0175 | N7: -0.130396
D8: Dalmia Bharat Limited | E8: DALBHARAT | F8: 1945.5 | G8: 18.753128 | H8: =F8*G8 -> 36484.211 | I8: 7334.2454 | J8: 5212.2645 | K8: 15171.801 | L8: 3050.9301 | M8: 1228.2427 | N8: 0.186865
D9: ACC Limited | E9: ACC | F9: 1396.2 | G9: 18.813405 | H9: =F9*G9 -> 26267.276 | I9: 502.73031 | J9: 302.8043 | K9: 25654.987 | L9: 3060.2584 | M9: 2744.2319 | N9: 0.006895
D10: J.K. Cement Limited | E10: 532644 | F10: 5487 | G10: 7.7303398 | H10: =F10*G10 -> 42416.374 | I10: 6741.6959 | J10: 1458.0463 | K10: 13894.066 | L10: 2520.6342 | M10: 1056.268 | N10: 0.336637
D11: The Ramco Cements Limited | E11: RAMCOCEM | F11: 984.5 | G11: 23.630562 | H11: =F11*G11 -> 23264.288 | I11: 4866.5234 | J11: 129.78363 | K11: 9129.7063 | L11: 1435.7961 | M11: 595.86343 | N11: 0.232481
D14: Back to Cover

Sheet Market Returns
A1: =Historical!A1 -> Shree Cement Ltd.
A2: Market Returns
D4: Date | E4: Index Closing Price
D5: 46142 | E5: 36174.8 | H5: Index | I5: Nifty 50 Total Return Index (Daily Returns)
D6: 46141 | E6: 36446.26
D7: 46140 | E7: 36172.04 | H7: Yearfrac | I7: =YEARFRAC(D2475,D5) -> 9.9861111
D8: 46139 | E8: 36318.25
D9: 46136 | E9: 36024.64 | H9: Market Returns | I9: =_xlfn.RRI(I7,E2475,E5) -> 0.13380019
D10: 46135 | E10: 36430.96
D11: 46134 | E11: 36739.93 | H11: 10Y Risk free rate | I11: 0.06929
D12: 46133 | E12: 37039.12
D13: 46132 | E13: 36719.99
D14: 46129 | E14: 36702.93 | H14: Back to Cover
D15: 46128 | E15: 36466.62
D16: 46127 | E16: 36518.69
D17: 46125 | E17: 35932.96
D18: 46122 | E18: 36246.4
D19: 46121 | E19: 35831.22
D20: 46120 | E20: 36166.14
D21: 46119 | E21: 34849.41
D22: 46118 | E22: 34615.19
D23: 46114 | E23: 34230.63
D24: 46113 | E24: 34179.9
D25: 46111 | E25: 33655.43
D26: 46108 | E26: 34391.13
... D2475: 42495 | E2475: 10322.82

Sheet WACC
A1: =Historical!A1 -> Shree Cement Ltd.
A2: Weighted-Average Cost of Capital (WACC)
G4: Equity | H4: Total | I4: Debt/ | J4: Debt/ | K4: Tax Rate | L4: Levered | M4: Unlevered
D5: Comparable Company Data | G5: Value | H5: Debt | I5: Equity | J5: Capital | K5: % | L5: Beta | M5: Beta
D6: ='Comps Valuation'!D7 -> UltraTech Cement Limited | G6: ='Comps Valuation'!J7 -> 337078.47 | H6: ='Comps Valuation'!K7 -> 26113.01 | I6: =H6/G6 -> 0.077468639 | J6: =H6/(H6+G6) -> 0.071898741 | K6: ='Comps Valuation'!Q7 -> 0.23731 | L6: 0.48 | M6: =L6/(1+I6*(1-K6)) -> 0.4532216
D7: ='Comps Valuation'!D8 -> Ambuja Cements Limited | G7: ='Comps Valuation'!J8 -> 109017.98 | H7: ='Comps Valuation'!K8 -> 1315.9803 | I7: =H7/G7 -> 0.012071223 | J7: =H7/(H7+G7) -> 0.011927246 | K7: ='Comps Valuation'!Q8 -> -0.130396 | L7: 0.05 | M7: =L7/(1+I7*(1-K7)) -> 0.049326921
D8: ='Comps Valuation'!D9 -> Dalmia Bharat Limited | G8: ='Comps Valuation'!J9 -> 36484.211 | H8: ='Comps Valuation'!K9 -> 7334.2454 | I8: =H8/G8 -> 0.20102519 | J8: =H8/(H8+G8) -> 0.16737799 | K8: ='Comps Valuation'!Q9 -> 0.186865 | L8: 0.16 | M8: =L8/(1+I8*(1-K8)) -> 0.13752077
D9: ='Comps Valuation'!D10 -> ACC Limited | G9: ='Comps Valuation'!J10 -> 26267.276 | H9: ='Comps Valuation'!K10 -> 502.73031 | I9: =H9/G9 -> 0.019139035 | J9: =H9/(H9+G9) -> 0.018779611 | K9: ='Comps Valuation'!Q10 -> 0.006895 | L9: 0.19 | M9: =L9/(1+I9*(1-K9)) -> 0.18645602
D10: ='Comps Valuation'!D11 -> J.K. Cement Limited | G10: ='Comps Valuation'!J11 -> 42416.374 | H10: ='Comps Valuation'!K11 -> 6741.6959 | I10: =H10/G10 -> 0.15894088 | J10: =H10/(H10+G10) -> 0.13714322 | K10: ='Comps Valuation'!Q11 -> 0.336637 | L10: 0.4 | M10: =L10/(1+I10*(1-K10)) -> 0.36184834
D11: ='Comps Valuation'!D12 -> The Ramco Cements Limited | G11: ='Comps Valuation'!J12 -> 23264.288 | H11: ='Comps Valuation'!K12 -> 4866.5234 | I11: =H11/G11 -> 0.20918428 | J11: =H11/(H11+G11) -> 0.1729962 | K11: ='Comps Valuation'!Q12 -> 0.232481 | L11: 0.12 | M11: =L11/(1+I11*(1-K11)) -> 0.10339899
D13: Average | I13: =AVERAGE(I6:I11) -> 0.11297154 | J13: =AVERAGE(J6:J11) -> 0.096687168 | K13: =AVERAGE(K6:K11) -> 0.14496533 | L13: =AVERAGE(L6:L11) -> 0.23333333 | M13: =AVERAGE(M6:M11) -> 0.21529544
D14: Median | I14: =MEDIAN(I6:I11) -> 0.11820476 | J14: =MEDIAN(J6:J11) -> 0.10452098 | K14: =MEDIAN(K6:K11) -> 0.209673 | L14: =MEDIAN(L6:L11) -> 0.175 | M14: =MEDIAN(M6:M11) -> 0.16198839
D16: ='Comps Valuation'!F17 -> SHREECEM | G16: ='Comps Valuation'!J17 -> 89806.657 | H16: ='Comps Valuation'!K17 -> 2218.2519
D18: WACC Calculation
D20: Target Capital Structure
D21: Proportion of Debt | E21: =J14 -> 0.10452098
D22: Proportion of Equity | E22: =1-E21 -> 0.89547902
D24: Current Capital Structure
D25: Market Cap | E25: =G16 -> 89806.657
D26: Total Debt | E26: =H16 -> 2218.2519
D27: Debt/Equity | E27: =E26/E25 -> 0.024700306
D29: Cost of Debt
D30: Pre-Tax Cost of Debt | E30: ='Financial Statements'!M14 -> 0.10974882
D31: Tax Rate | E31: ='Comps Valuation'!Q17 -> 0.246511
D32: After Tax Cost of Debt | E32: =E30*(1-E31) -> 0.082694528
D34: Cost of Equity
D35: Risk Free Rate | E35: ='Market Returns'!I11 -> 0.06929
D36: Equity Market Return | E36: ='Market Returns'!I9 -> 0.13380019
D37: Equity Risk Premium | E37: =E36-E35 -> 0.064510185
D38: Levered Equity Beta | E38: =M14*(1+E27*(1-E31)) -> 0.16500323
D39: Cost of Equity | E39: =E35+(E37*E38) -> 0.079934389
D41: WACC | E41: =(E21*E32)+(E22*E39) -> 0.080222881
D44: Back to Cover

Sheet Beta
A1: =Historical!A1 -> Shree Cement Ltd.
A2: Beta Calculation
B4: Date | C4: Index Closing Price | D4: % Change Monthly | E4: Stock Close Price | F4: % Change Monthly
B5: 46143 | C5: 76671.25 | E5: 24904.4 | H5: Index | I5: BSE Sensex 30, 5 Year Monthly data
B6: 46113 | C6: 76913.5 | D6: =C6/C5-1 -> 0.0031595937 | E6: 24156.5 | F6: =E6/E5-1 -> -0.030030838
B7: 46082 | C7: 71947.55 | D7: =C7/C6-1 -> -0.064565388 | E7: 23020.15 | F7: =E7/E6-1 -> -0.047041169 | H7: Min. (In Last 12 months) | I7: =MIN(E53:E64) -> 22130.1
B8: 46054 | C8: 81287.19 | D8: =C8/C7-1 -> 0.12981179 | E8: 26079.65 | F8: =E8/E7-1 -> 0.1329053 | H8: Max. (In Last 12 months) | I8: =MAX(E54:E65) -> 28925.6
B9: 46023 | C9: 82269.78 | D9: =C9/C8-1 -> 0.012087882 | E9: 26983.35 | F9: =E9/E8-1 -> 0.034651539
B10: 45992 | C10: 85220.6 | D10: =C10/C9-1 -> 0.035867605 | E10: 26563 | F10: =E10/E9-1 -> -0.015578125 | H10: Beta | I10: =SLOPE(F6:F64,D6:D64) -> 0.78750574
B11: 45962 | C11: 85706.67 | D11: =C11/C10-1 -> 0.0057036679 | E11: 26400.95 | F11: =E11/E10-1 -> -0.006100591 | H11: (Using Slope)
B12: 45931 | C12: 83938.71 | D12: =C12/C11-1 -> -0.020628033 | E12: 28288.35 | F12: =E12/E11-1 -> 0.071489852
B13: 45901 | C13: 80267.62 | D13: =C13/C12-1 -> -0.043735364 | E13: 29295.3 | F13: =E13/E12-1 -> 0.035595926 | H13: Beta | I13: =I33 -> 0.78750574
B14: 45870 | C14: 79809.65 | D14: =C14/C13-1 -> -0.0057055385 | E14: 29247.15 | F14: =E14/E13-1 -> -0.0016436084 | H14: (Using Regression)
B15: 45839 | C15: 81185.58 | D15: =C15/C14-1 -> 0.017240146 | E15: 30818.35 | F15: =E15/E14-1 -> 0.053721474
B16: 45809 | C16: 83606.46 | D16: =C16/C15-1 -> 0.029819089 | E16: 31029.65 | F16: =E16/E15-1 -> 0.0068563048 | H16: SUMMARY OUTPUT
B17: 45778 | C17: 81451.01 | D17: =C17/C16-1 -> -0.025780903 | E17: 29608.3 | F17: =E17/E16-1 -> -0.045806189
B18: 45748 | C18: 80242.24 | D18: =C18/C17-1 -> -0.014840454 | E18: 29730.7 | F18: =E18/E17-1 -> 0.0041339759 | H18: Regression Statistics
B19: 45717 | C19: 77414.92 | D19: =C19/C18-1 -> -0.035234809 | E19: 30501.95 | F19: =E19/E18-1 -> 0.025941199 | H19: Multiple R | I19: 0.48575543
B20: 45689 | C20: 73198.1 | D20: =C20/C19-1 -> -0.054470379 | E20: 27277.35 | F20: =E20/E19-1 -> -0.10571783 | H20: R Square | I20: 0.23595834
B21: 45658 | C21: 77500.57 | D21: =C21/C20-1 -> 0.058778438 | E21: 27829.9 | F21: =E21/E20-1 -> 0.020256733 | H21: Adjusted R Square | I21: 0.2225541
B22: 45627 | C22: 78139.01 | D22: =C22/C21-1 -> 0.0082378749 | E22: 25702.25 | F22: =E22/E21-1 -> -0.076451946 | H22: Standard Error | I22: 0.055606998
B23: 45597 | C23: 79802.79 | D23: =C23/C22-1 -> 0.021292566 | E23: 26060.2 | F23: =E23/E22-1 -> 0.013926796 | H23: Observations | I23: 59
B24: 45566 | C24: 79389.06 | D24: =C24/C23-1 -> -0.0051844052 | E24: 25072.7 | F24: =E24/E23-1 -> -0.037893032
B25: 45536 | C25: 84299.78 | D25: =C25/C24-1 -> 0.061856382 | E25: 26264.2 | F25: =E25/E24-1 -> 0.047521807 | H25: ANOVA
B26: 45505 | C26: 82365.77 | D26: =C26/C25-1 -> -0.022942053 | E26: 25474.2 | F26: =E26/E25-1 -> -0.030078967 | I26: df | J26: SS | K26: MS | L26: F | M26: Significance F
B27: 45474 | C27: 81741.34 | D27: =C27/C26-1 -> -0.0075811833 | E27: 27758.9 | F27: =E27/E26-1 -> 0.08968682 | H27: Regression | I27: 1 | J27: 0.054431718 | K27: 0.054431718 | L27: 17.603262 | M27: 9.6211922e-05
B28: 45444 | C28: 79032.73 | D28: =C28/C27-1 -> -0.033136354 | E28: 27878.6 | F28: =E28/E27-1 -> 0.0043121305 | H28: Residual | I28: 57 | J28: 0.17625188 | K28: 0.0030921383
B29: 45413 | C29: 73961.31 | D29: =C29/C28-1 -> -0.064168605 | E29: 24735.4 | F29: =E29/E28-1 -> -0.11274598 | H29: Total | I29: 58 | J29: 0.2306836
B30: 45383 | C30: 74482.78 | D30: =C30/C29-1 -> 0.0070505782 | E30: 24484.4 | F30: =E30/E29-1 -> -0.0101474
B31: 45352 | C31: 73651.35 | D31: =C31/C30-1 -> -0.011162714 | E31: 25703.8 | F31: =E31/E30-1 -> 0.04980314 | I31: Coefficients | J31: Standard Error | K31: t Stat | L31: P-value | M31: Lower 95% | N31: Upper 95% | O31: Lower 95.0% | P31: Upper 95.0%
B32: 45323 | C32: 72500.3 | D32: =C32/C31-1 -> -0.015628363 | E32: 25487.7 | F32: =E32/E31-1 -> -0.0084073172 | H32: Intercept | I32: 0.0080669632 | J32: 0.0073170367 | K32: 1.1024905 | L32: 0.2748818 | M32: -0.0065851499 | N32: 0.022719076 | O32: -0.0065851499 | P32: 0.022719076
B33: 45292 | C33: 71752.11 | D33: =C33/C32-1 -> -0.010319819 | E33: 28539 | F33: =E33/E32-1 -> 0.11971657 | H33: X Variable 1 | I33: 0.78750574 | J33: 0.18769692 | K33: 4.1956241 | L33: 9.6211922e-05 | M33: 0.41164913 | N33: 1.1633623 | O33: 0.41164913 | P33: 1.1633623
B34: 45261 | C34: 72240.26 | D34: =C34/C33-1 -> 0.0068032843 | E34: 28619.1 | F34: =E34/E33-1 -> 0.0028066856
B35: 45231 | C35: 66988.44 | D35: =C35/C34-1 -> -0.072699351 | E35: 26753.2 | F35: =E35/E34-1 -> -0.065197718
B36: 45200 | C36: 63874.93 | D36: =C36/C35-1 -> -0.046478318 | E36: 25661 | F36: =E36/E35-1 -> -0.040825023 | H36: Back to Cover
B37: 45170 | C37: 65828.41 | D37: =C37/C36-1 -> 0.030582891 | E37: 25472 | F37: =E37/E36-1 -> -0.0073652625
B38: 45139 | C38: 64831.41 | D38: =C38/C37-1 -> -0.015145436 | E38: 23806.9 | F38: =E38/E37-1 -> -0.065369818
B39: 45108 | C39: 66527.67 | D39: =C39/C38-1 -> 0.026164169 | E39: 24104.2 | F39: =E39/E38-1 -> 0.012487976
B40: 45078 | C40: 64718.56 | D40: =C40/C39-1 -> -0.027193347 | E40: 23892.3 | F40: =E40/E39-1 -> -0.0087909991
B41: 45047 | C41: 62622.24 | D41: =C41/C40-1 -> -0.032391326 | E41: 25198.6 | F41: =E41/E40-1 -> 0.054674519
...

Sheet Schedules
A1: ='Financial Statements'!A1 -> Shree Cement Ltd. | H1: Historical Information | M1: Forecasted Information
A2: Supporting Schedules | H2: ='Financial Statements'!H2 -> 2021 | I2: ='Financial Statements'!I2 -> 2022 | J2: ='Financial Statements'!J2 -> 2023 | K2: ='Financial Statements'!K2 -> 2024 | L2: ='Financial Statements'!L2 -> 2025 | M2: ='Financial Statements'!M2 -> 2026 | N2: ='Financial Statements'!N2 -> 2027 | O2: ='Financial Statements'!O2 -> 2028 | ... V2: ='Financial Statements'!V2 -> 2035
A4: Working Capital Schedule
D5: Account Receivables | H5: =Historical!H113 -> 416.99 | I5: =Historical!I113 -> -99.57 | J5: =Historical!J113 -> -606.22 | K5: =Historical!K113 -> -456.42 | L5: =Historical!L113 -> -43.03 | M5: ='Financial Statements'!L47-'Financial Statements'!M47 -> 131.91259 | N5: ='Financial Statements'!M47-'Financial Statements'!N47 -> -89.027012 | O5: ='Financial Statements'!N47-'Financial Statements'!O47 -> -89.07748 | P5: ='Financial Statements'!O47-'Financial Statements'!P47 -> -88.748341 | Q5: ='Financial Statements'!P47-'Financial Statements'!Q47 -> -88.066771 | R5: ='Financial Statements'!Q47-'Financial Statements'!R47 -> -87.062316 | S5: ='Financial Statements'!R47-'Financial Statements'!S47 -> -85.766024 | T5: ='Financial Statements'!S47-'Financial Statements'!T47 -> -84.209675 | ... V5: ='Financial Statements'!U47-'Financial Statements'!V47 -> -80.443655
D6: Inventory | H6: =Historical!H114 -> -8.97 | I6: =Historical!I114 -> -772.32 | J6: =Historical!J114 -> -235.02 | K6: =Historical!K114 -> -790.49 | L6: =Historical!L114 -> 1120.5 | M6: ='Financial Statements'!L48-'Financial Statements'!M48 -> -696.96639 | N6: ='Financial Statements'!M48-'Financial Statements'!N48 -> -220.23502 | O6: ='Financial Statements'!N48-'Financial Statements'!O48 -> -220.35987 | P6: ='Financial Statements'!O48-'Financial Statements'!P48 -> -219.54565 | Q6: ='Financial Statements'!P48-'Financial Statements'!Q48 -> -217.85958 | R6: ='Financial Statements'!Q48-'Financial Statements'!R48 -> -215.37476 | S6: ='Financial Statements'!R48-'Financial Statements'!S48 -> -212.16799 | T6: ='Financial Statements'!S48-'Financial Statements'!T48 -> -208.31789 | ... V6: ='Financial Statements'!U48-'Financial Statements'!V48 -> -199.00151
D7: Account Payables | H7: =Historical!H115 -> 484.68 | I7: =Historical!I115 -> 24.23 | J7: =Historical!J115 -> 789.65 | K7: =Historical!K115 -> 521.63 | L7: =Historical!L115 -> 328.37 | M7: ='Financial Statements'!M61-'Financial Statements'!L61 -> -0.73765436 | N7: ='Financial Statements'!N61-'Financial Statements'!M61 -> 95.390501 | O7: ='Financial Statements'!O61-'Financial Statements'!N61 -> 95.444575 | P7: ='Financial Statements'!P61-'Financial Statements'!O61 -> 95.09191 | Q7: ='Financial Statements'!Q61-'Financial Statements'!P61 -> 94.361623 | R7: ='Financial Statements'!R61-'Financial Statements'!Q61 -> 93.285371 | S7: ='Financial Statements'!S61-'Financial Statements'!R61 -> 91.896422 | T7: ='Financial Statements'!T61-'Financial Statements'!S61 -> 90.228829 | ... V7: ='Financial Statements'!V61-'Financial Statements'!U61 -> 86.193621
D8: Other | H8: 0 | I8: 0 | J8: 0 | K8: 0 | L8: 0 | M8: =L8 -> 0 | N8: =M8 -> 0 | O8: =N8 -> 0 | P8: =O8 -> 0 | Q8: =P8 -> 0 | R8: =Q8 -> 0 | S8: =R8 -> 0 | T8: =S8 -> 0 | ... V8: =U8 -> 0
D9: Total | H9: =SUM(H5:H8) -> 892.7 | I9: =SUM(I5:I8) -> -847.66 | J9: =SUM(J5:J8) -> -51.59 | K9: =SUM(K5:K8) -> -725.28 | L9: =SUM(L5:L8) -> 1405.84 | M9: =SUM(M5:M8) -> -565.79145 | N9: =SUM(N5:N8) -> -213.87153 | O9: =SUM(O5:O8) -> -213.99277 | ... V9: =SUM(V5:V8) -> -193.25155
A11: PP&E Schedule
D12: Opening PP&E | I12: =H15 -> 6711.04 | J12: =I15 -> 7777.71 | K12: =J15 -> 9590.35 | L12: =K15 -> 10764.62 | M12: =L15 -> 12344.39 | N12: =M15 -> 12125.584 | O12: =N15 -> 11986.846 | P12: =O15 -> 11905.095 | ... V12: =U15 -> 11356.969
D13: Plus: Capex | I13: =I15-I12-I14 -> 2212.55 | J13: =J15-J12-J14 -> 3473.31 | K13: =K15-K12-K14 -> 3071.59 | L13: =L15-L12-L14 -> 4586.55 | M13: =AVERAGE(I13:L13)*(1+0.5%) -> 3352.68 | N13: =M13*(1+0.5%) -> 3369.4434 | O13: =N13*(1+0.5%) -> 3386.2906 | P13: =O13*(1+0.5%) -> 3403.2221 | Q13: =P13*(1+0.5%) -> 3420.2382 | R13: =Q13*(1+0.5%) -> 3437.3394 | S13: =R13*(1+0.5%) -> 3454.5261 | T13: =S13*(1+0.5%) -> 3471.7987 | U13: =T13*(1+0.5%) -> 3489.1577 | V13: =U13*(1+0.5%) -> 3506.6035
D14: Less: Depreciation | H14: ='Financial Statements'!H33 -> -1262.34 | I14: ='Financial Statements'!I33 -> -1145.88 | J14: ='Financial Statements'!J33 -> -1660.67 | K14: ='Financial Statements'!K33 -> -1897.32 | L14: ='Financial Statements'!L33 -> -3006.78 | M14: =-M12*'Financial Statements'!M13 -> -3571.4862 | N14: =-N12*'Financial Statements'!N13 -> -3508.1811 | O14: =-O12*'Financial Statements'!O13 -> -3468.0414 | P14: =-P12*'Financial Statements'!P13 -> -3563.4402 | Q14: =-Q12*'Financial Statements'!Q13 -> -3515.4836 | R14: =-R12*'Financial Statements'!R13 -> -3486.9747 | S14: =-S12*'Financial Statements'!S13 -> -3588.1178 | T14: =-T12*'Financial Statements'!T13 -> -3546.7951 | ... V14: =-V12*'Financial Statements'!V13 -> -3626.514
D15: Closing PP&E | H15: ='Financial Statements'!H53 -> 6711.04 | I15: ='Financial Statements'!I53 -> 7777.71 | J15: ='Financial Statements'!J53 -> 9590.35 | K15: ='Financial Statements'!K53 -> 10764.62 | L15: ='Financial Statements'!L53 -> 12344.39 | M15: =SUM(M12:M14) -> 12125.584 | N15: =SUM(N12:N14) -> 11986.846 | O15: =SUM(O12:O14) -> 11905.095 | P15: =SUM(P12:P14) -> 11744.877 | Q15: =SUM(Q12:Q14) -> 11649.632 | R15: =SUM(R12:R14) -> 11599.997 | S15: =SUM(S12:S14) -> 11466.405 | T15: =SUM(T12:T14) -> 11391.408 | ... V15: =SUM(V12:V14) -> 11237.058
A17: DEBT SCHEDULE
D18: Opening Debt Balance | I18: =H20 -> 2229.88 | J18: =I20 -> 2129.22 | K18: =J20 -> 2724.67 | L18: =K20 -> 1655.55 | M18: =L20 -> 1046.13 | N18: =M20 -> 1046.13 | O18: =N20 -> 1046.13 | P18: =O20 -> 1046.13 | ... V18: =U20 -> 1046.13
D19: Issuance/ (Repayment) of Debt | I19: =I20-I18 -> -100.66 | J19: =J20-J18 -> 595.45 | K19: =K20-K18 -> -1069.12 | L19: =L20-L18 -> -609.42 | M19: 0 | N19: 0 | O19: 0 | P19: 0 | Q19: 0 | R19: 0 | S19: 0 | T19: 0 | U19: 0 | V19: 0
D20: Closing Debt Balance | H20: ='Financial Statements'!H65 -> 2229.88 | I20: ='Financial Statements'!I65 -> 2129.22 | J20: ='Financial Statements'!J65 -> 2724.67 | K20: ='Financial Statements'!K65 -> 1655.55 | L20: ='Financial Statements'!L65 -> 1046.13 | M20: =SUM(M18:M19) -> 1046.13 | N20: =SUM(N18:N19) -> 1046.13 | O20: =SUM(O18:O19) -> 1046.13 | P20: =SUM(P18:P19) -> 1046.13 | Q20: =SUM(Q18:Q19) -> 1046.13 | R20: =SUM(R18:R19) -> 1046.13 | S20: =SUM(S18:S19) -> 1046.13 | T20: =SUM(T18:T19) -> 1046.13 | ... V20: =SUM(V18:V19) -> 1046.13
D21: Interest | H21: ='Financial Statements'!H35 -> -251.29 | I21: ='Financial Statements'!I35 -> -216.12 | J21: ='Financial Statements'!J35 -> -262.87 | K21: ='Financial Statements'!K35 -> -258.34 | L21: ='Financial Statements'!L35 -> -204.96 | M21: =-M18*'Financial Statements'!M14 -> -114.81153 | N21: =-N18*'Financial Statements'!N14 -> -114.81153 | O21: =-O18*'Financial Statements'!O14 -> -114.81153 | P21: =-P18*'Financial Statements'!P14 -> -114.81153 | Q21: =-Q18*'Financial Statements'!Q14 -> -114.81153 | R21: =-R18*'Financial Statements'!R14 -> -114.81153 | S21: =-S18*'Financial Statements'!S14 -> -114.81153 | T21: =-T18*'Financial Statements'!T14 -> -114.81153 | ... V21: =-V18*'Financial Statements'!V14 -> -114.81153
D24: Back to Cover

Sheet Financial Statements
A1: =Historical!A1 -> Shree Cement Ltd. | H1: Historical Information | M1: Forecasted Information
A2: Financial Statements (All figures in INR Cr. Unless stated otherwise) | H2: 2021 | I2: =H2+1 -> 2022 | J2: =I2+1 -> 2023 | K2: =J2+1 -> 2024 | L2: =K2+1 -> 2025 | M2: =L2+1 -> 2026 | N2: =M2+1 -> 2027 | O2: =N2+1 -> 2028 | P2: =O2+1 -> 2029 | ... V2: =U2+1 -> 2035
D3: Master Check | H3: =IF(H77=0,"Perfect","Error") -> Perfect | I3: =IF(I77=0,"Perfect","Error") -> Perfect | J3: =IF(J77=0,"Perfect","Error") -> Perfect | K3: =IF(K77=0,"Perfect","Error") -> Perfect | L3: =IF(L77=0,"Perfect","Error") -> Perfect | M3: =IF(M77=0,"Perfect","Error") -> Perfect | N3: =IF(N77=0,"Perfect","Error") -> Perfect | O3: =IF(O77=0,"Perfect","Error") -> Perfect | ... V3: =IF(V77=0,"Perfect","Error") -> Perfect
D5: LIVE SCENARIO | E5: Base Case | G5: =IF($E$5='Revenue Scenarios'!D5,1,IF('Financial Statements'!$E$5='Revenue Scenarios'!D6,2,3)) -> 1
A7: Ratios and Assumptions
D8: Revenue Growth | F8: % | I8: ='Financial Statements'!I25/'Financial Statements'!H25-1 -> 0.10691848 | J8: ='Financial Statements'!J25/'Financial Statements'!I25-1 -> 0.18939729 | K8: ='Financial Statements'!K25/'Financial Statements'!J25-1 -> 0.14292084 | L8: ='Financial Statements'!L25/'Financial Statements'!K25-1 -> -0.054939276 | M8: {=CHOOSE('Financial Statements'!$G$5,'Revenue Scenarios'!H5:Q5,'Revenue Scenarios'!H6:Q6,'Revenue Scenarios'!H7:Q7)} -> 0.075 | N8: 0.070125 | O8: 0.065566875 | P8: 0.061305028 | Q8: 0.057320201 | R8: 0.053594388 | S8: 0.050110753 | T8: 0.046853554 | U8: 0.043808073 | V8: 0.040960548
D9: COGS | F9: % | H9: =-'Financial Statements'!H26/'Financial Statements'!H25 -> 0.31589105 | I9: =-'Financial Statements'!I26/'Financial Statements'!I25 -> 0.36565096 | J9: =-'Financial Statements'!J26/'Financial Statements'!J25 -> 0.47692766 | K9: =-'Financial Statements'!K26/'Financial Statements'!K25 -> 0.44620757 | L9: =-'Financial Statements'!L26/'Financial Statements'!L25 -> 0.41447184 | M9: =AVERAGE(H9:L9) -> 0.40382982 | N9: =M9 -> 0.40382982 | O9: =N9 -> 0.40382982 | P9: =O9 -> 0.40382982 | Q9: =P9 -> 0.40382982 | R9: =Q9 -> 0.40382982 | S9: =R9 -> 0.40382982 | T9: =S9 -> 0.40382982 | U9: =T9 -> 0.40382982 | V9: =U9 -> 0.40382982
D10: Salaries and Benefits (% of Revenue) | F10: % | H10: =-'Financial Statements'!H29/'Financial Statements'!H25 -> 0.064102857 | I10: =-'Financial Statements'!I29/'Financial Statements'!I25 -> 0.060858546 | J10: =-'Financial Statements'!J29/'Financial Statements'!J25 -> 0.054769882 | K10: =-'Financial Statements'!K29/'Financial Statements'!K25 -> 0.052168224 | L10: =-'Financial Statements'!L29/'Financial Statements'!L25 -> 0.059526014 | M10: =AVERAGE(H10:L10) -> 0.058285104 | N10: =M10 -> 0.058285104 | O10: =N10 -> 0.058285104 | P10: =O10 -> 0.058285104 | Q10: =P10 -> 0.058285104 | R10: =Q10 -> 0.058285104 | S10: =R10 -> 0.058285104 | T10: =S10 -> 0.058285104 | U10: =T10 -> 0.058285104 | V10: =U10 -> 0.058285104
D11: Freight And Forward Expenses | F11: % | H11: =-H30/H25 -> 0.16919977 | I11: =-I30/I25 -> 0.16449983 | J11: =-J30/J25 -> 0.15585977 | K11: =-K30/K25 -> 0.15870083 | L11: =-L30/L25 -> 0.17696417 | M11: =AVERAGE(H11:L11) -> 0.16504487 | N11: =M11 -> 0.16504487 | O11: =N11 -> 0.16504487 | P11: =O11 -> 0.16504487 | Q11: =P11 -> 0.16504487 | R11: =Q11 -> 0.16504487 | S11: =R11 -> 0.16504487 | T11: =S11 -> 0.16504487 | U11: =T11 -> 0.16504487 | V11: =U11 -> 0.16504487
D12: Other SG&A Expenses (% of Revenue) | F12: % | H12: =-'Financial Statements'!H31/'Financial Statements'!H25 -> 0.14995682 | I12: =-'Financial Statements'!I31/'Financial Statements'!I25 -> 0.16195278 | J12: =-'Financial Statements'!J31/'Financial Statements'!J25 -> 0.14666601 | K12: =-'Financial Statements'!K31/'Financial Statements'!K25 -> 0.12155579 | L12: =-'Financial Statements'!L31/'Financial Statements'!L25 -> 0.14502073 | M12: =AVERAGE(H12:L12) -> 0.14503043 | N12: =M12 -> 0.14503043 | O12: =N12 -> 0.14503043 | P12: =O12 -> 0.14503043 | Q12: =P12 -> 0.14503043 | R12: =Q12 -> 0.14503043 | S12: =R12 -> 0.14503043 | T12: =S12 -> 0.14503043 | U12: =T12 -> 0.14503043 | V12: =U12 -> 0.14503043
D13: Depreciation (% of PP&E) | F13: % | I13: =-'Financial Statements'!I33/Schedules!I12 -> 0.17074552 | J13: =-'Financial Statements'!J33/Schedules!J12 -> 0.21351657 | K13: =-'Financial Statements'!K33/Schedules!K12 -> 0.19783637 | L13: =-'Financial Statements'!L33/Schedules!L12 -> 0.27932059 | M13: =L13+1% -> 0.28932059 | N13: =M13 -> 0.28932059 | O13: =N13 -> 0.28932059 | P13: =O13+1% -> 0.29932059 | Q13: =P13 -> 0.29932059 | R13: =Q13 -> 0.29932059 | S13: =R13+1% -> 0.30932059 | T13: =S13 -> 0.30932059 | U13: =T13 -> 0.30932059 | V13: =U13+1% -> 0.31932059
D14: Interest (% of Debt) | F14: % | I14: =-'Financial Statements'!I35/Schedules!I18 -> 0.096920014 | J14: =-'Financial Statements'!J35/Schedules!J18 -> 0.12345836 | K14: =-'Financial Statements'!K35/Schedules!K18 -> 0.094815152 | L14: =-'Financial Statements'!L35/Schedules!L18 -> 0.12380176 | M14: =AVERAGE(I14:L14) -> 0.10974882 | N14: =M14 -> 0.10974882 | O14: =N14 -> 0.10974882 | P14: =O14 -> 0.10974882 | Q14: =P14 -> 0.10974882 | R14: =Q14 -> 0.10974882 | S14: =R14 -> 0.10974882 | T14: =S14 -> 0.10974882 | U14: =T14 -> 0.10974882 | V14: =U14 -> 0.10974882
D15: Other Income (Expenses) | F15: % | H15: ='Financial Statements'!H36/'Financial Statements'!H25 -> 0.032320607 | I15: ='Financial Statements'!I36/'Financial Statements'!I25 -> 0.036369487 | J15: ='Financial Statements'!J36/'Financial Statements'!J25 -> 0.025715411 | K15: ='Financial Statements'!K36/'Financial Statements'!K25 -> 0.029314147 | L15: ='Financial Statements'!L36/'Financial Statements'!L25 -> 0.030556718 | M15: =AVERAGE(H15:L15) -> 0.030855274 | N15: =M15 -> 0.030855274 | O15: =N15 -> 0.030855274 | P15: =O15 -> 0.030855274 | Q15: =P15 -> 0.030855274 | R15: =Q15 -> 0.030855274 | S15: =R15 -> 0.030855274 | T15: =S15 -> 0.030855274 | U15: =T15 -> 0.030855274 | V15: =U15 -> 0.030855274
D16: Taxes (% of EBT) | F16: % | H16: =-'Financial Statements'!H38/'Financial Statements'!H37 -> 0.23783987 | I16: =-'Financial Statements'!I38/'Financial Statements'!I37 -> 0.19199328 | J16: =-'Financial Statements'!J38/'Financial Statements'!J37 -> 0.15109964 | K16: =-'Financial Statements'!K38/'Financial Statements'!K37 -> 0.19026764 | L16: =-'Financial Statements'!L38/'Financial Statements'!L37 -> 0.1431251 | M16: =L16+0.5% -> 0.1481251 | N16: =M16 -> 0.1481251 | O16: =N16+0.5% -> 0.1531251 | P16: =O16 -> 0.1531251 | Q16: =P16+0.5% -> 0.1581251 | R16: =Q16 -> 0.1581251 | S16: =R16+0.5% -> 0.1631251 | T16: =S16 -> 0.1631251 | U16: =T16+0.5% -> 0.1681251 | V16: =U16 -> 0.1681251
D17: Dividend Payout | F17: % | H17: =-'Financial Statements'!H100/'Financial Statements'!H39 -> 0.0048611323 | I17: =-'Financial Statements'!I100/'Financial Statements'!I39 -> 0.16448188 | J17: =-'Financial Statements'!J100/'Financial Statements'!J39 -> 0.25570071 | K17: =-'Financial Statements'!K100/'Financial Statements'!K39 -> 0.15818226 | L17: =-'Financial Statements'!L100/'Financial Statements'!L39 -> 0.33802278 | M17: =AVERAGE(H17:L17) -> 0.18424975 | N17: =M17 -> 0.18424975 | O17: =N17 -> 0.18424975 | P17: =O17 -> 0.18424975 | Q17: =P17 -> 0.18424975 | R17: =Q17 -> 0.18424975 | S17: =R17 -> 0.18424975 | T17: =S17 -> 0.18424975 | U17: =T17 -> 0.18424975 | V17: =U17 -> 0.18424975
D18: Account Receivables | F18: Days | H18: ='Financial Statements'!H47/'Financial Statements'!H25*365 -> 18.288802 | I18: ='Financial Statements'!I47/'Financial Statements'!I25*365 -> 19.169506 | J18: ='Financial Statements'!J47/'Financial Statements'!J25*365 -> 24.771167 | K18: ='Financial Statements'!K47/'Financial Statements'!K25*365 -> 23.01451 | L18: ='Financial Statements'!L47/'Financial Statements'!L25*365 -> 26.527896 | M18: =AVERAGE(H18:L18) -> 22.354376 | N18: =M18 -> 22.354376 | O18: =N18 -> 22.354376 | P18: =O18 -> 22.354376 | Q18: =P18 -> 22.354376 | R18: =Q18 -> 22.354376 | S18: =R18 -> 22.354376 | T18: =S18 -> 22.354376 | U18: =T18 -> 22.354376 | V18: =U18 -> 22.354376
D19: Days Inventory Outstanding (DIO) | F19: Days | H19: =-'Financial Statements'!H48/'Financial Statements'!H26*365 -> 146.20076 | I19: =-'Financial Statements'!I48/'Financial Statements'!I26*365 -> 166.0658 | J19: =-'Financial Statements'!J48/'Financial Statements'!J26*365 -> 118.30529 | K19: =-'Financial Statements'!K48/'Financial Statements'!K26*365 -> 142.52565 | L19: =-'Financial Statements'!L48/'Financial Statements'!L26*365 -> 111.60002 | M19: =AVERAGE(H19:L19) -> 136.93951 | N19: =M19 -> 136.93951 | O19: =N19 -> 136.93951 | P19: =O19 -> 136.93951 | Q19: =P19 -> 136.93951 | R19: =Q19 -> 136.93951 | S19: =R19 -> 136.93951 | T19: =S19 -> 136.93951 | U19: =T19 -> 136.93951 | V19: =U19 -> 136.93951
D20: Account Payables | F20: Days | H20: =-'Financial Statements'!H61/'Financial Statements'!H26*365 -> 75.240066 | I20: =-'Financial Statements'!I61/'Financial Statements'!I26*365 -> 59.214587 | J20: =-'Financial Statements'!J61/'Financial Statements'!J26*365 -> 51.271571 | K20: =-'Financial Statements'!K61/'Financial Statements'!K26*365 -> 48.679469 | L20: =-'Financial Statements'!L61/'Financial Statements'!L26*365 -> 62.157675 | M20: =AVERAGE(H20:L20) -> 59.312674 | N20: =M20 -> 59.312674 | O20: =N20 -> 59.312674 | P20: =O20 -> 59.312674 | Q20: =P20 -> 59.312674 | R20: =Q20 -> 59.312674 | S20: =R20 -> 59.312674 | T20: =S20 -> 59.312674 | U20: =T20 -> 59.312674 | V20: =U20 -> 59.312674
A23: =Historical!A4 -> PROFIT & LOSS STATEMENT
C24: INCOME
D25: Revenue | F25: =Historical!F7 -> ₹ in Cr | H25: =Historical!H9 -> 13559.77 | I25: =Historical!I9 -> 15009.56 | J25: =Historical!J9 -> 17852.33 | K25: =Historical!K9 -> 20403.8 | L25: =Historical!L9 -> 19282.83 | M25: =L25*(1+'Financial Statements'!M8) -> 20729.042 | N25: =M25*(1+'Financial Statements'!N8) -> 22182.666 | O25: =N25*(1+'Financial Statements'!O8) -> 23637.114 | P25: =O25*(1+'Financial Statements'!P8) -> 25086.188 | Q25: =P25*(1+'Financial Statements'!Q8) -> 26524.134 | R25: =Q25*(1+'Financial Statements'!R8) -> 27945.679 | S25: =R25*(1+'Financial Statements'!S8) -> 29346.058 | T25: =S25*(1+'Financial Statements'!T8) -> 30721.025 | ... V25: =U25*(1+'Financial Statements'!V8) -> 33380.329
D26: COGS | H26: =-SUM(Historical!H13:H15,Historical!H17,Historical!H19) -> -4283.41 | I26: =-SUM(Historical!I13:I15,Historical!I17,Historical!I19) -> -5488.26 | J26: =-SUM(Historical!J13:J15,Historical!J17,Historical!J19) -> -8514.27 | K26: =-SUM(Historical!K13:K15,Historical!K17,Historical!K19) -> -9104.33 | L26: =-SUM(Historical!L13:L15,Historical!L17,Historical!L19) -> -7992.19 | M26: =-M25*'Financial Statements'!M9 -> -8371.0053 | N26: =-N25*'Financial Statements'!N9 -> -8958.0221 | O26: =-O25*'Financial Statements'!O9 -> -9545.3716 | P26: =-P25*'Financial Statements'!P9 -> -10130.551 | Q26: =-Q25*'Financial Statements'!Q9 -> -10711.236 | R26: =-R25*'Financial Statements'!R9 -> -11285.298 | S26: =-S25*'Financial Statements'!S9 -> -11850.813 | T26: =-T25*'Financial Statements'!T9 -> -12406.066 | ... V26: =-V25*'Financial Statements'!V9 -> -13479.972
D27: Gross Profit | H27: =SUM(H25:H26) -> 9276.36 | I27: =SUM(I25:I26) -> 9521.3 | J27: =SUM(J25:J26) -> 9338.06 | K27: =SUM(K25:K26) -> 11299.47 | L27: =SUM(L25:L26) -> 11290.64 | M27: =SUM(M25:M26) -> 12358.037 | N27: =SUM(N25:N26) -> 13224.644 | O27: =SUM(O25:O26) -> 14091.743 | ... V27: =SUM(V25:V26) -> 19900.357
C28: EXPENSES
D29: Employee Salaries and Benefits | H29: =-Historical!H16 -> -869.22 | I29: =-Historical!I16 -> -913.46 | J29: =-Historical!J16 -> -977.77 | K29: =-Historical!K16 -> -1064.43 | L29: =-Historical!L16 -> -1147.83 | M29: =-M25*'Financial Statements'!M10 -> -1208.1944 | N29: =-N25*'Financial Statements'!N10 -> -1292.919 | O29: =-O25*'Financial Statements'!O10 -> -1377.6917 | P29: =-P25*'Financial Statements'!P10 -> -1462.1511 | Q29: =-Q25*'Financial Statements'!Q10 -> -1545.9619 | R29: =-R25*'Financial Statements'!R10 -> -1628.8168 | S29: =-S25*'Financial Statements'!S10 -> -1710.438 | T29: =-T25*'Financial Statements'!T10 -> -1790.5781 | ... V29: =-V25*'Financial Statements'!V10 -> -1945.576
D30: Freight And Forward Expenses | H30: =-Historical!H18 -> -2294.31 | I30: =-Historical!I18 -> -2469.07 | J30: =-Historical!J18 -> -2782.46 | K30: =-Historical!K18 -> -3238.1 | L30: =-Historical!L18 -> -3412.37 | M30: =-M25*M11 -> -3421.2221 | N30: =-N25*N11 -> -3661.1353 | O30: =-O25*O11 -> -3901.1846 | P30: =-P25*P11 -> -4140.3468 | Q30: =-Q25*Q11 -> -4377.6723 | R30: =-R25*R11 -> -4612.291 | S30: =-S25*S11 -> -4843.4163 | T30: =-T25*T11 -> -5070.3476 | ... V30: =-V25*V11 -> -5509.2522
D31: Other SG&A Expenses | H31: =-SUM(Historical!H22:H23) -> -2033.38 | I31: =-SUM(Historical!I22:I23) -> -2430.84 | J31: =-SUM(Historical!J22:J23) -> -2618.33 | K31: =-SUM(Historical!K22:K23) -> -2480.2 | L31: =-SUM(Historical!L22:L23) -> -2796.41 | M31: =-M25*'Financial Statements'!M12 -> -3006.3418 | N31: =-N25*'Financial Statements'!N12 -> -3217.1615 | O31: =-O25*'Financial Statements'!O12 -> -3428.1008 | P31: =-P25*'Financial Statements'!P12 -> -3638.2606 | Q31: =-Q25*'Financial Statements'!Q12 -> -3846.8064 | R31: =-R25*'Financial Statements'!R12 -> -4052.9736 | S31: =-S25*'Financial Statements'!S12 -> -4256.0712 | T31: =-T25*'Financial Statements'!T12 -> -4455.4833 | ... V31: =-V25*'Financial Statements'!V12 -> -4841.1634
D32: EBITDA | H32: =SUM(H27:H31) -> 4079.45 | I32: =SUM(I27:I31) -> 3707.93 | J32: =SUM(J27:J31) -> 2959.5 | K32: =SUM(K27:K31) -> 4516.74 | L32: =SUM(L27:L31) -> 3934.03 | M32: =SUM(M27:M31) -> 4722.2786 | N32: =SUM(N27:N31) -> 5053.4284 | O32: =SUM(O27:O31) -> 5384.7659 | ... V32: =SUM(V27:V31) -> 7604.3655
D33: Depreciation & Amortization | H33: =-Historical!H21 -> -1262.34 | I33: =-Historical!I21 -> -1145.88 | J33: =-Historical!J21 -> -1660.67 | K33: =-Historical!K21 -> -1897.32 | L33: =-Historical!L21 -> -3006.78 | M33: =Schedules!M14 -> -3571.4862 | N33: =Schedules!N14 -> -3508.1811 | O33: =Schedules!O14 -> -3468.0414 | P33: =Schedules!P14 -> -3563.4402 | Q33: =Schedules!Q14 -> -3515.4836 | R33: =Schedules!R14 -> -3486.9747 | S33: =Schedules!S14 -> -3588.1178 | T33: =Schedules!T14 -> -3546.7951 | ... V33: =Schedules!V14 -> -3626.514
D34: EBIT | H34: =SUM(H32:H33) -> 2817.11 | I34: =SUM(I32:I33) -> 2562.05 | J34: =SUM(J32:J33) -> 1298.83 | K34: =SUM(K32:K33) -> 2619.42 | L34: =SUM(L32:L33) -> 927.25 | M34: =SUM(M32:M33) -> 1150.7924 | N34: =SUM(N32:N33) -> 1545.2473 | O34: =SUM(O32:O33) -> 1916.7245 | ... V34: =SUM(V32:V33) -> 3977.8515
D35: Interest | H35: =-Historical!H20 -> -251.29 | I35: =-Historical!I20 -> -216.12 | J35: =-Historical!J20 -> -262.87 | K35: =-Historical!K20 -> -258.34 | L35: =-Historical!L20 -> -204.96 | M35: =Schedules!M21 -> -114.81153 | N35: =Schedules!N21 -> -114.81153 | O35: =Schedules!O21 -> -114.81153 | P35: =Schedules!P21 -> -114.81153 | Q35: =Schedules!Q21 -> -114.81153 | R35: =Schedules!R21 -> -114.81153 | S35: =Schedules!S21 -> -114.81153 | T35: =Schedules!T21 -> -114.81153 | ... V35: =Schedules!V21 -> -114.81153
D36: Other Income (Expenses) | H36: =Historical!H10 -> 438.26 | I36: =Historical!I10 -> 545.89 | J36: =Historical!J10 -> 459.08 | K36: =Historical!K10 -> 598.12 | L36: =Historical!L10 -> 589.22 | M36: =M25*'Financial Statements'!M15 -> 639.60028 | N36: =N25*'Financial Statements'!N15 -> 684.45225 | O36: =O25*'Financial Statements'!O15 -> 729.32965 | P36: =P25*'Financial Statements'!P15 -> 774.04122 | Q36: =Q25*'Financial Statements'!Q15 -> 818.40942 | R36: =R25*'Financial Statements'!R15 -> 862.27157 | S36: =S25*'Financial Statements'!S15 -> 905.48065 | T36: =T25*'Financial Statements'!T15 -> 947.90564 | ... V36: =V25*'Financial Statements'!V15 -> 1029.9592
D37: EBT | H37: =SUM(H34:H36) -> 3004.08 | I37: =SUM(I34:I36) -> 2891.82 | J37: =SUM(J34:J36) -> 1495.04 | K37: =SUM(K34:K36) -> 2959.2 | L37: =SUM(L34:L36) -> 1311.51 | M37: =SUM(M34:M36) -> 1675.5811 | N37: =SUM(N34:N36) -> 2114.888 | O37: =SUM(O34:O36) -> 2531.2426 | ... V37: =SUM(V34:V36) -> 4892.9992
D38: Taxes | H38: =-Historical!H30 -> -714.49 | I38: =-Historical!I30 -> -555.21 | J38: =-Historical!J30 -> -225.9 | K38: =-Historical!K30 -> -563.04 | L38: =-Historical!L30 -> -187.71 | M38: =-M37*'Financial Statements'!M16 -> -248.19562 | N38: =-N37*'Financial Statements'!N16 -> -313.268 | O38: =-O37*'Financial Statements'!O16 -> -387.59678 | P38: =-P37*'Financial Statements'!P16 -> -430.38391 | Q38: =-Q37*'Financial Statements'!Q16 -> -510.83443 | R38: =-R37*'Financial Statements'!R16 -> -573.48563 | S38: =-S37*'Financial Statements'!S16 -> -634.20923 | T38: =-T37*'Financial Statements'!T16 -> -698.9664 | ... V38: =-V37*'Financial Statements'!V16 -> -822.63598
D39: PAT | H39: =SUM(H37:H38) -> 2289.59 | I39: =SUM(I37:I38) -> 2336.61 | J39: =SUM(J37:J38) -> 1269.14 | K39: =SUM(K37:K38) -> 2396.16 | L39: =SUM(L37:L38) -> 1123.8 | M39: =SUM(M37:M38) -> 1427.3855 | N39: =SUM(N37:N38) -> 1801.62 | O39: =SUM(O37:O38) -> 2143.6458 | ... V39: =SUM(V37:V38) -> 4070.3632
A42: =Historical!A34 -> BALANCE SHEET
B43: ASSETS:
C44: Current Assets
D45: Cash & Equivalents | F45: =Historical!F7 -> ₹ in Cr | H45: =Historical!H54-17.46 -> 454.68 | I45: =Historical!I54-28.03 -> 120.53 | J45: =Historical!J54-36.14 -> 10.03 | K45: =Historical!K54-67.07 -> 195.29 | L45: =Historical!L54-23.69 -> 117.46 | M45: =M106 -> 934.86483 | N45: =N106 -> 2329.4029 | O45: =O106 -> 3945.8405 | P45: =P106 -> 5834.5744 | Q45: =Q106 -> 7936.8812 | R45: =R106 -> 10268.094 | S45: =S106 -> 12849.823 | T45: =T106 -> 15647.705 | ... V45: =V106 -> 21890.876
D46: Bank Deposits | H46: =Historical!H55+17.46 -> 253.67 | I46: =Historical!I55+28.03 -> 169.12 | J46: =Historical!J55+36.14 -> 150.9 | K46: =Historical!K55+67.07 -> 226.52 | L46: =Historical!L55+23.69-7.27595761418343E-12 -> 176.12 | M46: =L46 -> 176.12 | N46: =M46 -> 176.12 | O46: =N46 -> 176.12 | P46: =O46 -> 176.12 | Q46: =P46 -> 176.12 | R46: =Q46 -> 176.12 | S46: =R46 -> 176.12 | T46: =S46 -> 176.12 | ... V46: =U46 -> 176.12
...

Sheet DCF
A1: =Historical!A1 -> Shree Cement Ltd. | H1: Historical Information | M1: Forecasted Information
A2: Discounted Cashflow Analysis- Valuation | H2: ='Financial Statements'!H2 -> 2021 | I2: ='Financial Statements'!I2 -> 2022 | J2: ='Financial Statements'!J2 -> 2023 | K2: ='Financial Statements'!K2 -> 2024 | L2: ='Financial Statements'!L2 -> 2025 | M2: ='Financial Statements'!M2 -> 2026 | N2: ='Financial Statements'!N2 -> 2027 | O2: ='Financial Statements'!O2 -> 2028 | ... V2: ='Financial Statements'!V2 -> 2035
A4: DCF Valuation
D6: Assumptions
D7: Transaction Date | E7: 46128
D8: Fiscal year end | E8: =EOMONTH(E7,11) -> 46477
D9: Tax Rate | E9: ='Comps Valuation'!Q17 -> 0.246511
D10: EV/EBITDA Multiple | E10: ='Comps Valuation'!S17 -> 14.768261
D11: Perpetual Growth Rate | E11: 0.04
D12: Discount rate (WACC) | E12: =WACC!E41 -> 0.080222881
D13: Shared Outstanding (in Cr.) | E13: ='Comps Valuation'!I17 -> 3.6081421
D14: Current Market Price | E14: ='Comps Valuation'!H17 -> 24890
A17: Unlevered Free Cash Flow
H18: Historical Information | M18: Forecasted Information
D19: Discounted Cash Flow | H19: =H2 -> 2021 | I19: =I2 -> 2022 | J19: =J2 -> 2023 | K19: =K2 -> 2024 | L19: =L2 -> 2025 | M19: Entry Date | N19: =M2 -> 2026 | O19: =N2 -> 2027 | P19: =O2 -> 2028 | Q19: =P2 -> 2029 | R19: =Q2 -> 2030 | S19: =R2 -> 2031 | T19: =S2 -> 2032 | U19: =T2 -> 2033 | ... W19: =V2 -> 2035 | X19: Exit
D20: Date | M20: =E7 -> 46128 | N20: =DATE(YEAR($E$8)-1,MONTH($E$8),DAY($E$8)) -> 46112 | O20: =DATE(YEAR($E$8)+O21,MONTH($E$8),DAY($E$8)) -> 46477 | P20: =DATE(YEAR($E$8)+P21,MONTH($E$8),DAY($E$8)) -> 46843 | Q20: =DATE(YEAR($E$8)+Q21,MONTH($E$8),DAY($E$8)) -> 47208 | R20: =DATE(YEAR($E$8)+R21,MONTH($E$8),DAY($E$8)) -> 47573 | S20: =DATE(YEAR($E$8)+S21,MONTH($E$8),DAY($E$8)) -> 47938 | T20: =DATE(YEAR($E$8)+T21,MONTH($E$8),DAY($E$8)) -> 48304 | U20: =DATE(YEAR($E$8)+U21,MONTH($E$8),DAY($E$8)) -> 48669 | V20: =DATE(YEAR($E$8)+V21,MONTH($E$8),DAY($E$8)) -> 49034 | W20: =DATE(YEAR($E$8)+W21,MONTH($E$8),DAY($E$8)) -> 49399 | X20: =W20 -> 49399
D21: Time Period | N21: 0 | O21: 0 | P21: =O21+1 -> 1 | Q21: =P21+1 -> 2 | R21: =Q21+1 -> 3 | S21: =R21+1 -> 4 | T21: =S21+1 -> 5 | U21: =T21+1 -> 6 | V21: =U21+1 -> 7 | W21: =V21+1 -> 8
D22: Yearfrac | O22: =YEARFRAC(M20,O20) -> 0.95833333 | P22: =YEARFRAC(O20,P20) -> 1 | Q22: =YEARFRAC(P20,Q20) -> 1 | R22: =YEARFRAC(Q20,R20) -> 1 | S22: =YEARFRAC(R20,S20) -> 1 | T22: =YEARFRAC(S20,T20) -> 1 | U22: =YEARFRAC(T20,U20) -> 1 | V22: =YEARFRAC(U20,V20) -> 1 | W22: =YEARFRAC(V20,W20) -> 1 | X22: =W22 -> 1
D24: EBIT | E24: ='Financial Statements'!F25 -> ₹ in Cr | I24: ='Financial Statements'!I34 -> 2562.05 | J24: ='Financial Statements'!J34 -> 1298.83 | K24: ='Financial Statements'!K34 -> 2619.42 | L24: ='Financial Statements'!L34 -> 927.25 | N24: ='Financial Statements'!M34 -> 1150.7924 | O24: ='Financial Statements'!N34 -> 1545.2473 | P24: ='Financial Statements'!O34 -> 1916.7245 | Q24: ='Financial Statements'!P34 -> 2151.4389 | R24: ='Financial Statements'!Q34 -> 2526.9735 | S24: ='Financial Statements'!R34 -> 2879.3242 | T24: ='Financial Statements'!S34 -> 3097.2012 | U24: ='Financial Statements'!T34 -> 3451.7548 | ... W24: ='Financial Statements'!V34 -> 3977.8515
D25: Less: Cash Tax | I25: ='Financial Statements'!I38 -> -555.21 | J25: ='Financial Statements'!J38 -> -225.9 | K25: ='Financial Statements'!K38 -> -563.04 | L25: ='Financial Statements'!L38 -> -187.71 | N25: ='Financial Statements'!M38 -> -248.19562 | O25: ='Financial Statements'!N38 -> -313.268 | P25: ='Financial Statements'!O38 -> -387.59678 | Q25: ='Financial Statements'!P38 -> -430.38391 | R25: ='Financial Statements'!Q38 -> -510.83443 | S25: ='Financial Statements'!R38 -> -573.48563 | T25: ='Financial Statements'!S38 -> -634.20923 | U25: ='Financial Statements'!T38 -> -698.9664 | ... W25: ='Financial Statements'!V38 -> -822.63598
D26: NOPAT | I26: =SUM(I24:I25) -> 2006.84 | J26: =SUM(J24:J25) -> 1072.93 | K26: =SUM(K24:K25) -> 2056.38 | L26: =SUM(L24:L25) -> 739.54 | N26: =SUM(N24:N25) -> 902.59677 | O26: =SUM(O24:O25) -> 1231.9793 | P26: =SUM(P24:P25) -> 1529.1277 | Q26: =SUM(Q24:Q25) -> 1721.055 | R26: =SUM(R24:R25) -> 2016.1391 | S26: =SUM(S24:S25) -> 2305.8386 | T26: =SUM(T24:T25) -> 2462.9919 | U26: =SUM(U24:U25) -> 2752.7884 | ... W26: =SUM(W24:W25) -> 3155.2155
D27: Plus: D&A | I27: =-'Financial Statements'!I33 -> 1145.88 | J27: =-'Financial Statements'!J33 -> 1660.67 | K27: =-'Financial Statements'!K33 -> 1897.32 | L27: =-'Financial Statements'!L33 -> 3006.78 | N27: =-'Financial Statements'!M33 -> 3571.4862 | O27: =-'Financial Statements'!N33 -> 3508.1811 | P27: =-'Financial Statements'!O33 -> 3468.0414 | Q27: =-'Financial Statements'!P33 -> 3563.4402 | R27: =-'Financial Statements'!Q33 -> 3515.4836 | S27: =-'Financial Statements'!R33 -> 3486.9747 | T27: =-'Financial Statements'!S33 -> 3588.1178 | U27: =-'Financial Statements'!T33 -> 3546.7951 | ... W27: =-'Financial Statements'!V33 -> 3626.514
D28: Less: Capex | I28: =-Schedules!I13 -> -2212.55 | J28: =-Schedules!J13 -> -3473.31 | K28: =-Schedules!K13 -> -3071.59 | L28: =-Schedules!L13 -> -4586.55 | N28: =-Schedules!M13 -> -3352.68 | O28: =-Schedules!N13 -> -3369.4434 | P28: =-Schedules!O13 -> -3386.2906 | Q28: =-Schedules!P13 -> -3403.2221 | R28: =-Schedules!Q13 -> -3420.2382 | S28: =-Schedules!R13 -> -3437.3394 | T28: =-Schedules!S13 -> -3454.5261 | U28: =-Schedules!T13 -> -3471.7987 | ... W28: =-Schedules!V13 -> -3506.6035
D29: Less: Changes in Net WC | I29: =Schedules!I9 -> -847.66 | J29: =Schedules!J9 -> -51.59 | K29: =Schedules!K9 -> -725.28 | L29: =Schedules!L9 -> 1405.84 | N29: =Schedules!M9 -> -565.79145 | O29: =Schedules!N9 -> -213.87153 | P29: =Schedules!O9 -> -213.99277 | Q29: =Schedules!P9 -> -213.20208 | R29: =Schedules!Q9 -> -211.56473 | S29: =Schedules!R9 -> -209.1517 | T29: =Schedules!S9 -> -206.03759 | U29: =Schedules!T9 -> -202.29874 | ... W29: =Schedules!V9 -> -193.25155
D30: Unlevered Free Cash Flow | I30: =SUM(I26:I29) -> 92.51 | J30: =SUM(J26:J29) -> -791.3 | K30: =SUM(K26:K29) -> 156.83 | L30: =SUM(L26:L29) -> 565.61 | M30: 0 | N30: =SUM(N26:N29) -> 555.6115 | O30: =SUM(O26:O29) -> 1156.8454 | P30: =SUM(P26:P29) -> 1396.8857 | Q30: =SUM(Q26:Q29) -> 1668.071 | R30: =SUM(R26:R29) -> 1899.8198 | S30: =SUM(S26:S29) -> 2146.3222 | T30: =SUM(T26:T29) -> 2390.5461 | U30: =SUM(U26:U29) -> 2625.4861 | ... W30: =SUM(W26:W29) -> 3081.8745 | X30: =S38 -> 95993.992
D32: Transaction Cash flow | M32: 0 | O32: =O30*O22 -> 1108.6435 | P32: =P30*P22 -> 1396.8857 | Q32: =Q30*Q22 -> 1668.071 | R32: =R30*R22 -> 1899.8198 | S32: =S30*S22 -> 2146.3222 | T32: =T30*T22 -> 2390.5461 | U32: =U30*U22 -> 2625.4861 | V32: =V30*V22 -> 2835.1552 | ... X32: =X30*X22 -> 95993.992
D35: Intrinsic Value (Using Implied Value) | I35: Market Value (Using Facts) | M35: Rate of Return | Q35: Terminal Value
D36: Enterprise Value | F36: =XNPV(E12,O32:X32,O20:X20) -> 65257.87 | I36: Market Cap | K36: =E13*E14 -> 89806.657 | M36: Market Price | O36: =K42 -> 24890 | Q36: EV/EBITDA | S36: =(W24+W27)*E10 -> 112303.25
D37: Plus: Cash and Equivalents (Inc. financial Assets) | F37: =SUM('Financial Statements'!L45:L46,'Financial Statements'!L55,'Financial Statements'!L49) -> 8289.8 | I37: Plus: Debt | K37: =-F38 -> 1046.13 | M37: Target Price | O37: =F42 -> 20082.571 | Q37: Perpetual Growth | S37: =W30*(1+E11)/(E12-E11) -> 79684.732
D38: Less: Debt | F38: =-Schedules!L20 -> -1046.13 | I38: Less: Cash & Equivalents (Inc. Fin Assets) | K38: =-F37 -> -8289.8 | M38: Potential | O38: =O37/O36-1 -> -0.193147 | Q38: Average | S38: =AVERAGE(S36:S37) -> 95993.992
D39: Less: Non- Controlling Interest | F39: =-'Financial Statements'!L73 -> -40.77 | I39: Plus: NCI | K39: =-F39 -> 40.77
D40: Equity Value | F40: =SUM(F36:F39) -> 72460.77 | I40: Enterprise Value | K40: =SUM(K36:K39) -> 82603.757
D42: Equity Value per Share | F42: =F40/E13 -> 20082.571 | I42: Equity Value Per Share | K42: =K36/E13 -> 24890
D43: (Target Price) | I43: (Market Price)
A46: SENSITIVITY ANALYSIS
H48: Sensitivity Analysis (Intrinsic Value (INR/Share)
J50: Exit multiple
H51: Discount Rate | I51: =F42 -> 20082.571 | J51: 10 | K51: 12 | L51: 14.768261 | M51: 16 | N51: 18
I52: 0.06 | J52: 26597.518 | K52: 27919.403 | L52: 29749.065 | M52: 30563.174 | N52: 31885.059
I53: 0.07 | J53: 20639.838 | K53: 21866 | L53: 23563.169 | M53: 24318.326 | N53: 25544.489
...

Sheet Comps Valuation
A1: =Historical!A1 -> Shree Cement Ltd.
A2: Comps Valuation
F4: Market Data | M4: Financial Data | R4: Valuation Metrices
H5: Stock Price | I5: Shares | J5: Market Cap | L5: Cash and | M5: Enterprise Value | Q5: Effective | S5: EV/
D6: Company Name | F6: Ticker | H6: INR/Share | I6: In Cr. | J6: In INR Cr. | K6: Debt | L6: Equivalents | M6: in INR Cr. | N6: Sales | O6: EBITDA | P6: Earnings | Q6: Tax Rate | R6: EV/Sales | S6: EBITDA | T6: P/E Ratio
D7: ='Comps Data'!D6 -> UltraTech Cement Limited | F7: ='Comps Data'!E6 -> ULTRACEMCO | H7: ='Comps Data'!F6 -> 11452 | I7: ='Comps Data'!G6 -> 29.434026 | J7: ='Comps Data'!H6 -> 337078.47 | K7: ='Comps Data'!I6 -> 26113.01 | L7: ='Comps Data'!J6 -> 3811.6224 | M7: =J7+K7-L7 -> 359379.85 | N7: ='Comps Data'!K6 -> 88830.512 | O7: ='Comps Data'!L6 -> 16522.795 | P7: ='Comps Data'!M6 -> 7937.9277 | Q7: ='Comps Data'!N6 -> 0.23731 | R7: =M7/N7 -> 4.0456803 | S7: =M7/O7 -> 21.750548 | T7: =J7/P7 -> 42.46429
