Workbook

Sheet Cover page
D4: Ugar Sugar Works Ltd.
E7: Financial Modelling and Valuation Analysis
C10: Company : Ugar Sugar Works Ltd. | I10: xxxx | J10: Inputs / Assumptions
C11: Ticker : NSE: UGARSUGAR, BSE: 530363 | I11: xxxx | J11: Formulae
C12: Sector : FMCG | I12: xxxx | J12: Linking/ Reference cell
C13: Industry : Agricultural Food & other Products
C14: Sub-Industry: Sugar
C15: Analyst : Manish Rathour
F17: INDEX
D19: Assumptions
D20: Revenue Growth Scenarios
D21: Historical Information
D22: Comps Data
D23: Assumptions Data
D24: Working Schedules
D25: Financial Statements
D26: DCF Valuation
D27: Sensitivity Analysis
D28: Comps Valuation
D29: Ratio Analysis & Interpretation
D30: Market Returns
... D33: Valuation Summary- Football Analysis

Sheet Assumptions->

Sheet Assumptions
A1: ='Historical Info'!A1 -> Ugar Sugar Works Ltd.
A2: Assumptions
D4: Company Description | E4: Ugar Sugar Works Ltd.
D5: ISIN Code | E5: INE071E01023
D6: Sector Name | E6: FMCG
D7: Industry | E7: Agricultural Food & other Products
D8: Exchange Name | E8: NSE: UGARSUGAR, BSE: 530363
D9: Website | E9: https://www.ugarsugar.com/
D10: Company Description | E10: The Ugar Sugar Works Ltd, established in 1939 as the flagship of the Shirgaokar Group, is the largest single-location sugar producer in Southern India with a combined crushing capacity of 18,000 TCD across its Ugar Khurd and Jewargi plants. The company operates a highly integrated model, manufacturing various grades of white crystal sugar and unique export-oriented sugar cubes while leveraging byproducts for a 44 MW co-generation power plant and a 75,000-litre daily capacity distillery producing ethanol and IML brands like Old Castle and Ugar XXX Rum. Publicly traded on the NSE and BSE, the firm reported revenues of ₹1,420 Cr for FY2025 and remains a key player in India's ethanol blending initiatives under the leadership of the Shirgaokar family.
D11: Current Market Price | E11: 39.33
D50: Scenario
D51: Base Case | F51: 1
D54: Company Data
D55: Particulars | G55: Amount
D56: No of Outstanding shares | E56: Unit | G56: ='Comps (Data)'!D11*10^5 -> 1.1253063e+08
D57: Face Value per share | E57: Rs. | G57: 1
D58: Current Market Price | E58: Rs. | G58: =E11 -> 39.33
D59: Market Capitalisation | E59: INR in Lakh | G59: ='Comps (Data)'!E11 -> 44258.298
D62: Assumptions
D63: Perpetual Growth rate | E63: % | G63: =DCF!E11 -> 0.04
D64: 10 year Bond yield rate | E64: % | G64: =Market_Returns!F7 -> 0.06961
D65: Interest rate | E65: % | G65: ='Comps (Data)'!K11 -> 0.27409762
D68: Particular | E68: Assumptions
D69: Revenue Buildup | E69: Using bottom-up, segment-wise method, I computed the weighted average revenue growth rate for the company. Based on historical data, I derived Base Case revenue growth rate of 9.86% (Calculations given in Worksheet 'Assumptions (Data)'. I then forecasted revenue using this base case as the anchor, applying a +5% Premium for the Bull Case (14.86%) supported by stronger Sugar and Distellary growth projections by CRISIL, and a -5% haircut for the Bear Case to adjust for downside risks such as a correction in sugar prices and a softening of distillery demand, Climate risk etc. Since historical peer revenue CAGRs for listed Indian sugar businesses range from -2.8% to +14.8%, I selected ±5% as my sensitivity band since it is a realistic and statistically sound swing around my base estimate.
D70: Cost Buildup | E70: I have assumed COGS, Salaries & Benefits, and Other SG&A Expenses to grow at the historical average growth rate, derived from FY2021–FY2025 data, and kept constant throughout the forecast period. These cost heads are operationally linked to revenue volume and have exhibited stable historical trends, making the average growth rate the most reliable anchor for projection.
E71: D&A as a % of PP&E has ranged from 7.8% to 11.1% historically. In the forecast period, I have assumed it to gradually increase by 2% in every 3 years, starting at 8.3% in FY2026F, stepping up to 14.3% by FY2035F. Assuming that the company continues to invest in capacity expansion- particularly in the distillery and ethanol segment- the asset base deepens, leading to progressively higher depreciation charges as a proportion of PP&E over time.
E72: I have normalized the interest rate to 9.4%, representing the most recently observed stable rate in FY2025, and held it constant throughout the forecast period. Interest expense in each forecast year is calculated as 9.4% applied to the opening debt balance from the Debt & Interest Schedule. This approach reflects a stable borrowing cost assumption absent any guidance on refinancing or new debt issuances.
E73: Other Income (Expense) is assumed to grow at the average growth rate of Historical years, Keeping them constant going forward.
E74: Historically the effective tax rate has been erratic- ranging from 6.6% to 30.6%, largely due to deferred tax adjustments and prior year losses. As the company stabilizes its profitability, I have assumed a gradual convergence (by 0.5% increase in every 2 years) towards the statutory corporate tax rate of 30%, stepping up from 27% in FY2026F to 29% by FY2035F, reflecting the normalization of tax provisions over time.
D75: Balance Sheet Items | E75: I have averaged historical Capex over FY2021–FY2025 and assumed it grows at 0.5% per year through the forecast period. The adjusted Capex is allocated to PP&E in proportion to the asset composition observed in FY2025 (the latest audited year). This reflects continued but measured capital investment in Ugar's distillery and ethanol expansion without assuming step-change capacity additions.
E76: PP&E is forecasted using PP&E Schedule, Opening PP&E for each year is sourced from the closing balance of the prior year. Capex additions and depreciation charges are computed from the Depreciation Schedule in the Working Schedules tab.
E77: Bank Deposits, Other Current Assets, Goodwill, Financial Assets, Other Non-Current Assets, Other Current & Non-Current Liabilities are held constant at their FY2025 audited levels throughout the forecast period As no company disclosures, management guidance, or industry data were available to support a directional assumption.
E78: Non-Controlling Interest is assumed to be zero throughout the forecast period. Ugar Sugar Works does not have a material NCI position based on the latest audited financial statements, and no disclosures indicate any anticipated change in ownership structure.
E79: The dividend payout ratio is assumed to grow at the historical average growth rate of 10.3% per year, consistent with the company's observed payout trajectory over FY2021–FY2025. Keeping it constant throughout the forecast period. Absolute dividend outflow is derived from PAT multiplied by the forecasted payout ratio in each year.
E80: Equity Share Capital is held constant at the FY2025 level of ₹1125 Lakhs throughout the forecast period. The company has not announced any plans for a rights issue, ESOP dilution, or buyback, and the face value remains unchanged.
E81: Cash and Cash Equivalents serve as the balancing figure in the Balance Sheet for each forecast year. The closing cash balance is derived from the Cash Flow Statement (Operating + Investing + Financing cash flows), ensuring internal consistency across all three financial statements.
E82: DSO, DIO, and DPO are computed using a 365-day convention and assumed to grow at their respective historical average growth rates derived from FY2021–FY2025 data. These ratios are then used to back-calculate Trade Receivables, Inventory, and Trade Payables as a function of Revenue and COGS respectively in each forecast year.
D83: Working Capital | E83: Trade Receivables, Inventory, and Trade Payables are forecasted using the working capital turnover ratios (DSO, DIO, DPO) derived from historical averages. All three are grown at their historical average rates and are directly linked to the Revenue and COGS drivers in the Income Statement, maintaining operational consistency in working capital modeling.
D84: Cash Flow Statement | E84: Sale of PP&E: Set to zero throughout the forecast period. Ugar Sugar Works is in an active capex and capacity expansion phase. No asset disposals have been disclosed or are expected based on available information.
E85: Advance Given for Investment: Set it to zero throughout the forecast period. No guidance or disclosure supports forecasting any new investment advances; held flat to avoid speculative assumptions.
...

Sheet Rev Growth Scenarios
A1: ='Historical Info'!A1 -> Ugar Sugar Works Ltd.
A2: Revenue Growth Scenarios
D4: Scenarios | E4: Growth (%) | H4: ='Financial Statements'!M2 -> 2026 | I4: ='Financial Statements'!N2 -> 2027 | J4: ='Financial Statements'!O2 -> 2028 | K4: ='Financial Statements'!P2 -> 2029 | L4: ='Financial Statements'!Q2 -> 2030 | M4: ='Financial Statements'!R2 -> 2031 | N4: ='Financial Statements'!S2 -> 2032 | O4: ='Financial Statements'!T2 -> 2033 | ... Q4: ='Financial Statements'!V2 -> 2035
D5: Base Case | E5: 0.098639712 | H5: =E5 -> 0.098639712 | I5: =H5*(1-$E$8) -> 0.089268939 | J5: =I5*(1-$E$8) -> 0.08078839 | K5: =J5*(1-$E$8) -> 0.073113493 | L5: =K5*(1-$E$8) -> 0.066167711 | M5: =L5*(1-$E$8) -> 0.059881778 | N5: =M5*(1-$E$8) -> 0.054193009 | O5: =N5*(1-$E$8) -> 0.049044674 | P5: =O5*(1-$E$8) -> 0.04438543 | Q5: =P5*(1-$E$8) -> 0.040168814
D6: Bull Case | E6: =E5+0.05 -> 0.14863971 | H6: =E6 -> 0.14863971 | I6: =H6*(1-$E$8) -> 0.13451894 | J6: =I6*(1-$E$8) -> 0.12173964 | K6: =J6*(1-$E$8) -> 0.11017437 | L6: =K6*(1-$E$8) -> 0.099707809 | M6: =L6*(1-$E$8) -> 0.090235567 | N6: =M6*(1-$E$8) -> 0.081663188 | O6: =N6*(1-$E$8) -> 0.073905185 | P6: =O6*(1-$E$8) -> 0.066884192 | Q6: =P6*(1-$E$8) -> 0.060530194
D7: Bear Case | E7: =E5-0.05 -> 0.048639712 | H7: =E7 -> 0.048639712 | I7: =H7*(1-$E$8) -> 0.044018939 | J7: =I7*(1-$E$8) -> 0.03983714 | K7: =J7*(1-$E$8) -> 0.036052612 | L7: =K7*(1-$E$8) -> 0.032627613 | M7: =L7*(1-$E$8) -> 0.02952799 | N7: =M7*(1-$E$8) -> 0.026722831 | O7: =N7*(1-$E$8) -> 0.024184162 | P7: =O7*(1-$E$8) -> 0.021886667 | Q7: =P7*(1-$E$8) -> 0.019807433
D8: Annual Growth Tempering | E8: 0.095
D11: Back to Cover

Sheet Inputs->

Sheet Historical Info
A1: Ugar Sugar Works Ltd.
A2: Historical Information
A4: INCOME STATEMENT | H4: 2021 | I4: =H4+1 -> 2022 | J4: =I4+1 -> 2023 | K4: =J4+1 -> 2024 | L4: =K4+1 -> 2025
C5: Revenues
D6: Revenue From Operations | H6: 111796.48 | I6: 130158.9 | J6: 194014.95 | K6: 127723.66 | L6: 140741.27
D7: Other Income | H7: 586.52 | I7: 224.47 | J7: 642.31 | K7: 3307.94 | L7: 1339.29
D8: Total Income (I+II) | H8: =SUM(H6:H7) -> 112383 | I8: =SUM(I6:I7) -> 130383.37 | J8: =SUM(J6:J7) -> 194657.26 | K8: =SUM(K6:K7) -> 131031.6 | L8: =SUM(L6:L7) -> 142080.56
C9: Expenses
D10: (a) Cost of materials consumed | H10: 77572.52 | I10: 98413.84 | J10: 92449.88 | K10: 94241.6 | L10: 105950.84
D11: (b) Other Manufacturing Expenses | H11: 2219.92 | I11: 3195.97 | J11: 3512.82 | K11: 4432.82 | L11: 5352.22
D12: (c) Purchases of Stock-in-Trade | H12: 3930.52 | I12: 4670.84 | J12: 7352.83 | K12: 6422.66 | L12: 4021.48
D13: (d) Changes in inventories of finished goods, Stock-in-Trade and work-in-progress | H13: -4320.56 | I13: -13653.24 | J13: 40257.98 | K13: -10557.71 | L13: 1395.61
D14: (e) Employee benefits expenses | H14: 6949.56 | I14: 7843.89 | J14: 10793.89 | K14: 9452.44 | L14: 8846.52
D15: (f) Finance costs | H15: 4261.32 | I15: 4353.84 | J15: 4859.52 | K15: 4440.26 | L15: 4843.39
D16: (g) Excise Duty on Goods Sold | H16: 16245.12 | I16: 16412.94 | J16: 14597.38 | K16: 12602.51 | L16: 7758.32
D17: (h) Depreciation and amortization expense | H17: 1242.62 | I17: 1148.05 | J17: 1807.97 | K17: 2908.21 | L17: 2750.21
D18: (i) Other expenses | H18: 2421.85 | I18: 3360.4 | J18: 4185.75 | K18: 4108.67 | L18: 3373.08
D19: Total expenses (IV) | H19: =SUM(H10:H18) -> 110522.87 | I19: =SUM(I10:I18) -> 125746.53 | J19: =SUM(J10:J18) -> 179818.02 | K19: =SUM(K10:K18) -> 128051.46 | L19: =SUM(L10:L18) -> 144291.67
D20: Profit/(loss) before exceptional items and tax from continuing operations | H20: 1860.13 | I20: 4636.84 | J20: 14839.24 | K20: 2980.14 | L20: -2211.11
D21: Exceptional Items | H21: 0 | I21: 0 | J21: 0 | K21: 0 | L21: 0
D22: Profit/(loss) before tax from continuing operations | H22: 1860.13 | I22: 4636.84 | J22: 14839.24 | K22: 2980.14 | L22: -2211.11
D23: Tax expense:
D24: Current tax | H24: 309.44 | I24: 1272.16 | J24: 3555.61 | K24: 793.96 | L24: 0
D25: MAT Credit entitlement for current year | H25: 0 | I25: -952.36 | J25: 0 | K25: 0 | L25: 0
D26: MAT Credit entitlement for earlier year | H26: 0 | I26: 0 | J26: 818.23 | K26: 0 | L26: 0
D27: Deferred tax | H27: -154.37 | I27: -15.8 | J27: 160.6 | K27: 71.93 | L27: -586.16
D28: Total Taxes (Net) | H28: =H24+H25+H26+H27 -> 155.07 | I28: =I24+I25+I26+I27 -> 304 | J28: =J24+J25+J26+J27 -> 4534.44 | K28: =K24+K25+K26+K27 -> 865.89 | L28: =L24+L25+L26+L27 -> -586.16
D29: Profit/(Loss) for the period | H29: =H22-SUM(H24:H27) -> 1705.06 | I29: =I22-SUM(I24:I27) -> 4332.84 | J29: =J22-SUM(J24:J27) -> 10304.8 | K29: =K22-SUM(K24:K27) -> 2114.25 | L29: =L22-SUM(L24:L27) -> -1624.95
A33: BALANCE SHEET | H33: =H4 -> 2021 | I33: =I4 -> 2022 | J33: =J4 -> 2023 | K33: =K4 -> 2024 | L33: =L4 -> 2025
B34: ASSETS
C35: Non-current Assets
D36: Tangible Assets:
D37: Property, plant and equipment | H37: 12833.05 | I37: 11867.63 | J37: 22356.39 | K37: 25365.01 | L37: 23390.18
D38: Capital work in progress | H38: 259.61 | I38: 11222.81 | J38: 3785.97 | K38: 7928.47 | L38: 14829.11
D39: Investment property | H39: 7.56 | I39: 7.12 | J39: 6.7 | K39: 6.33 | L39: 5.97
D40: Intangible Assets | H40: 0 | J40: 0 | K40: 0 | L40: 0
D41: Other Intangible assets | H41: 2.8 | I41: 2.52 | J41: 9.1 | K41: 7.65 | L41: 3.52
D42: Financial assets:
D43: Non - Current Investments | H43: 371.85 | I43: 366.97 | J43: 358.57 | K43: 353.57 | L43: 508.53
D44: Non - Current Loans & Advances | H44: 3.5 | I44: 3.5 | J44: 0 | K44: 0 | L44: 0
...

Sheet Comps (Data)
A1: Company | B1: Ticker | C1: Stock Price | D1: Weighted Avg. Shares Outstanding Dil | E1: Market Cap | F1: Total Debt | G1: Cash And Equivalents & Short term investments | H1: Total Revenues | I1: EBITDA | J1: Net Income (Income Statement) | K1: Effective Tax Rate | L1: Revenue 10Y CAGR | M1: Revenue 5Y CAGR | N1: Short-term Borrowings
A2: Mawana Sugars Limited | B2: 523371 | C2: 79.5 | D2: 390.99666 | E2: 31097.907 | F2: 19559.408 | G2: 1521.7 | H2: 152953.44 | I2: 12085.844 | J2: 10172.867 | K2: 0.164934 | M2: 0.029027 | N2: 6199.5331
A3: DCM Shriram Industries Limited | B3: 523369 | C3: 37.59 | D3: 869.54098 | E3: 32700.362 | F3: 57177.206 | G3: 11028.9 | H3: 213747.05 | I3: 18989.116 | J3: 9313.5687 | K3: 0.354496 | L3: 0.046803 | M3: 0.021199 | N3: 4822.6084
A4: Magadh Sugar & Energy Limited | B4: MAGADSUGAR | C4: 417.8 | D4: 140.44682 | E4: 58874.83 | F4: 75737.668 | G4: 133.5 | H4: 138761.06 | I4: 20908.76 | J4: 10519.333 | K4: 0.256562 | M4: 0.068992 | N4: 5140.6163
A5: Dwarikesh Sugar Industries Limited | B5: 532610 | C5: 33.33 | D5: 1846.9899 | E5: 61760.98 | F5: 54311.716 | G5: 29261.02 | H5: 152377.14 | I5: 11954.825 | J5: 2535.2519 | K5: 0.564909 | L5: 0.088695 | M5: 0.003634 | N5: 3824.8669
A6: Avadh Sugar & Energy Limited | B6: AVADHSUGAR | C6: 322.35 | D6: 200.22026 | E6: 64529.377 | F6: 146798.27 | G6: 372.8 | H6: 283126.79 | I6: 26403.179 | J6: 7584.426 | K6: 0.35483 | M6: -2.4e-05 | N6: 10580.313
A7: Davangere Sugar Company Limited | B7: DAVANGERE | C7: 4.59 | D7: 7290.8429 | E7: 46392.038 | F7: 38172.128 | G7: 1220.1 | H7: 20717.142 | I7: 5768.9815 | J7: 1210.0573 | K7: 0.145261 | L7: 0.020181 | M7: 0.022582 | N7: 2109.233
A8: Dhampur Sugar Mills Limited | B8: 500119 | C8: 113.2 | D8: 652.05772 | E8: 72794.968 | F8: 100215.12 | G8: 25153.076 | H8: 211870.06 | I8: 17567.145 | J8: 5514.3263 | K8: 0.302683 | L8: 0.003379 | M8: -0.114763 | N8: 7522.4878
A9: Uttam Sugar Mills Limited | B9: 532729 | C9: 208.7 | D9: 381.55192 | E9: 79594.256 | F9: 28639.377 | G9: 2093.5 | H9: 227501.8 | I9: 25616.294 | J9: 11632.761 | K9: 0.265864 | L9: 0.110827 | M9: 0.039236 | N9: 7809.5786
A11: The Ugar Sugar Works Limited | B11: 530363 | C11: =Assumptions!E11 -> 39.33 | D11: 1125.3063 | E11: =C11*D11 -> 44258.298 | F11: 45440.079 | G11: 1916.7361 | H11: 159888.72 | I11: 7657.5538 | J11: 1002.5592 | K11: =AVERAGE('Ratio Analysis & Interpretation'!M13:Q13) -> 0.27409762 | L11: 0.131631 | M11: 0.117959 | N11: 3659.7222
D13: The date was in INR Million so converted it into INR Lakhs | G13: 10
A16: Back to Cover

Sheet Assumptions (Data)
A1: ='Historical Info'!A1 -> Ugar Sugar Works Ltd.
A2: Revenue growth Assumption- Data (Values are in INR Lakhs)
D4: Assumptions for Revenue Growth (Base Case Scenario)
D5: Segment wise Revenue contribution- FY-2025
D6: Segment & Product | E6: Revenue | F6: Weightage in Rev. | G6: Industry Growth Rate
D7: i. SUGAR | E7: 53334.21 | F7: =E7/E18 -> 0.37911086 | G7: 0.1
D8: ii. DISTILLERY | F8: {=SUM(E9:E12/E18)} -> 0.50015446 | G8: 0.1
D9: a. Rectified Spirit | E9: 26.7
D10: b. Denatured Spirit | E10: 0
D11: c. Potable Alcohol | E11: 9147.59
D12: d. Biofuel | E12: 61188.62
D13: iii. OTHERS | F13: {=SUM(E14:E17/E18)} -> 0.12073468 | G13: =F41 -> 0.088733243
D14: a. Electricity | E14: 2144.41
D15: b. Petroleum Products | E15: 4130.01
D16: c. Broken Rice | E16: 0
D17: d. By-Products & Others | E17: 10710.82
D18: Total | E18: =SUM(E7:E17) -> 140682.36 | F18: =E18/E18 -> 1 | G18: =(F7*G7)+(F8*G8)+(F13*G13) -> 0.098639712 | H18: (Weighted-average revenue growth rate: base case)
D20: Factors that I considered to make segment wise industry growth rate assumptions
C21: i. Sugar
D22: India’s sugar production increased by 58% over the past decade, reflecting a long-term CAGR of around 4.7%, representing the steady but moderate structural growth.
D23: Based on CRISIL Ratings reports as of June 2025, "India's gross sugar production is expected to rise by approximately 15% in the 2025-26 season to around 35 million tonnes."
D24: Sugar is expected to see 15% growth in FY 2025-26, so will take 10% average growth rate
C25: ii. Distillery
D26: Ugar Sugar is clearly prioritizing and strengthening its distillery business alongside sugar, because distillery offers higher margins, more stable demand, and policy-driven growth visibility.
D27: India achieves 20% ethanol blending target- ISMA IBEF July 28, 2025
D28: Ethanol production grew from 380 million litres (2014) to 6,610 million litres (2025)
D29: This is a 17.4× increase over 11 years
D30: It gave the CAGR of 29.6% over the last 11 years
D31: Since India has achieved the 20% Ethanol Blending target so now its in Maturity phase
D32: The optimum growth of Distillery would be: 8-12%
C34: iii. OTHERS | E34: 2021 | F34: =E34+1 -> 2022 | G34: =F34+1 -> 2023 | H34: =G34+1 -> 2024 | I34: =H34+1 -> 2025
D35: a. Electricity | E35: 4437.75 | F35: 4866.03 | G35: 4920.06 | H35: 3629.41 | I35: 2144.41
D36: b. Petroleum Products | E36: 4065.69 | F36: 4769.59 | G36: 4839.69 | H36: 4206.24 | I36: 4130.01
D37: c. Broken Rice | E37: 0 | F37: 0 | G37: 0 | H37: 842.74 | I37: 0
D38: d. By-Products & Others | E38: 3673.99 | F38: 3500.89 | G38: 6072.86 | H38: 8717.02 | I38: 10710.8
D39: Total Revenue of Other products | E39: =SUM(E35:E38) -> 12177.43 | F39: =SUM(F35:F38) -> 13136.51 | G39: =SUM(G35:G38) -> 15832.61 | H39: =SUM(H35:H38) -> 17395.41 | I39: =SUM(I35:I38) -> 16985.22
D40: Historical Growth rate | F40: =F39/E39-1 -> 0.078758819 | G40: =G39/F39-1 -> 0.20523716 | H40: =H39/G39-1 -> 0.098707667 | I40: =I39/H39-1 -> -0.023580358
D41: OTHERS Median growth rate | F41: =MEDIAN(F40:I40) -> 0.088733243
D44: Other Assumptions
C45: 1 | D45: the depreciation rate grows once every 3 years by 2%. % does not change.
...

Sheet Working Schedules
A1: ='Historical Info'!A1 -> Ugar Sugar Works Ltd.
A2: Revenue Growth Scenarios
A4: Supporting Schedules | H4: ='Financial Statements'!H2 -> 2021 | I4: ='Financial Statements'!I2 -> 2022 | J4: ='Financial Statements'!J2 -> 2023 | K4: ='Financial Statements'!K2 -> 2024 | L4: ='Financial Statements'!L2 -> 2025 | M4: ='Financial Statements'!M2 -> 2026 | N4: ='Financial Statements'!N2 -> 2027 | O4: ='Financial Statements'!O2 -> 2028 | ... V4: ='Financial Statements'!V2 -> 2035
C6: Working Capital Schedule | F6: ='Financial Statements'!F61 -> ₹ in Lakhs
D7: Accounts Receivables | H7: ='Historical Info'!H98 -> -2975.16 | I7: ='Historical Info'!I98 -> -3703.61 | J7: ='Historical Info'!J98 -> -11675.45 | K7: ='Historical Info'!K98 -> 468.14 | L7: ='Historical Info'!L98 -> 3990.86 | M7: ='Financial Statements'!L31-'Financial Statements'!M31 -> -505.70939 | N7: ='Financial Statements'!M31-'Financial Statements'!N31 -> -1120.1984 | O7: ='Financial Statements'!N31-'Financial Statements'!O31 -> -1104.2785 | P7: ='Financial Statements'!O31-'Financial Statements'!P31 -> -1080.1097 | Q7: ='Financial Statements'!P31-'Financial Statements'!Q31 -> -1048.9677 | R7: ='Financial Statements'!Q31-'Financial Statements'!R31 -> -1012.1298 | S7: ='Financial Statements'!R31-'Financial Statements'!S31 -> -970.82786 | T7: ='Financial Statements'!S31-'Financial Statements'!T31 -> -926.21315 | ... V7: ='Financial Statements'!U31-'Financial Statements'!V31 -> -831.11838
D8: Inventory | H8: ='Historical Info'!H99 -> -4734.61 | I8: ='Historical Info'!I99 -> -13437.27 | J8: ='Historical Info'!J99 -> 40418.14 | K8: ='Historical Info'!K99 -> -11976.36 | L8: ='Historical Info'!L99 -> -4125.13 | M8: ='Financial Statements'!L32-'Financial Statements'!M32 -> -13120.15 | N8: ='Financial Statements'!M32-'Financial Statements'!N32 -> -5869.6157 | O8: ='Financial Statements'!N32-'Financial Statements'!O32 -> -5786.1991 | P8: ='Financial Statements'!O32-'Financial Statements'!P32 -> -5659.5594 | Q8: ='Financial Statements'!P32-'Financial Statements'!Q32 -> -5496.3813 | R8: ='Financial Statements'!Q32-'Financial Statements'!R32 -> -5303.3582 | S8: ='Financial Statements'!R32-'Financial Statements'!S32 -> -5086.9441 | T8: ='Financial Statements'!S32-'Financial Statements'!T32 -> -4853.1719 | ... V8: ='Financial Statements'!U32-'Financial Statements'!V32 -> -4354.8943
D9: Accounts Payables | H9: ='Historical Info'!H100 -> -7459.68 | I9: ='Historical Info'!I100 -> 16326.45 | J9: ='Historical Info'!J100 -> -7963.4 | K9: ='Historical Info'!K100 -> -524.52 | L9: ='Historical Info'!L100 -> -2690.39 | M9: ='Financial Statements'!M44-'Financial Statements'!L44 -> 6722.3627 | N9: ='Financial Statements'!N44-'Financial Statements'!M44 -> 1656.1962 | O9: ='Financial Statements'!O44-'Financial Statements'!N44 -> 1632.6589 | P9: ='Financial Statements'!P44-'Financial Statements'!O44 -> 1596.9257 | Q9: ='Financial Statements'!Q44-'Financial Statements'!P44 -> 1550.8827 | R9: ='Financial Statements'!R44-'Financial Statements'!Q44 -> 1496.4185 | S9: ='Financial Statements'!S44-'Financial Statements'!R44 -> 1435.3541 | T9: ='Financial Statements'!T44-'Financial Statements'!S44 -> 1369.392 | ... V9: ='Financial Statements'!V44-'Financial Statements'!U44 -> 1228.7958
D10: Other | H10: 0 | I10: 0 | J10: 0 | K10: 0 | L10: 0 | M10: =('Financial Statements'!L33-'Financial Statements'!M33)+('Financial Statements'!M45-'Financial Statements'!L45) -> 0 | N10: =('Financial Statements'!M33-'Financial Statements'!N33)+('Financial Statements'!N45-'Financial Statements'!M45) -> 0 | O10: =('Financial Statements'!N33-'Financial Statements'!O33)+('Financial Statements'!O45-'Financial Statements'!N45) -> 0 | P10: =('Financial Statements'!O33-'Financial Statements'!P33)+('Financial Statements'!P45-'Financial Statements'!O45) -> 0 | Q10: =('Financial Statements'!P33-'Financial Statements'!Q33)+('Financial Statements'!Q45-'Financial Statements'!P45) -> 0 | R10: =('Financial Statements'!Q33-'Financial Statements'!R33)+('Financial Statements'!R45-'Financial Statements'!Q45) -> 0 | S10: =('Financial Statements'!R33-'Financial Statements'!S33)+('Financial Statements'!S45-'Financial Statements'!R45) -> 0 | T10: =('Financial Statements'!S33-'Financial Statements'!T33)+('Financial Statements'!T45-'Financial Statements'!S45) -> 0 | ... V10: =('Financial Statements'!U33-'Financial Statements'!V33)+('Financial Statements'!V45-'Financial Statements'!U45) -> 0
D11: Total | H11: =SUM(H7:H10) -> -15169.45 | I11: =SUM(I7:I10) -> -814.43 | J11: =SUM(J7:J10) -> 20779.29 | K11: =SUM(K7:K10) -> -12032.74 | L11: =SUM(L7:L10) -> -2824.66 | M11: =SUM(M7:M10) -> -6903.4966 | N11: =SUM(N7:N10) -> -5333.618 | O11: =SUM(O7:O10) -> -5257.8187 | ... V11: =SUM(V7:V10) -> -3957.2169
C13: Depreciation Schedule
D14: PP&E Opening balance | I14: =H17 -> 13092.66 | J14: =I17 -> 23090.44 | K14: =J17 -> 26142.36 | L14: =K17 -> 33293.48 | M14: =L17 -> 38219.29 | N14: =M17 -> 43497.451 | O14: =N17 -> 48381.785 | P14: =O17 -> 51937.4 | ... V14: =U17 -> 62170.087
D15: Plus: Capex | I15: =I17-I14-I16 -> 11145.83 | J15: =J17-J14-J16 -> 4859.9 | K15: =K17-K14-K16 -> 10059.33 | L15: =L17-L14-L16 -> 7676.01 | M15: =AVERAGE(I15:L15) -> 8435.2675 | N15: =M15*(1+0.5%) -> 8477.4438 | O15: =N15*(1+0.5%) -> 8519.8311 | P15: =O15*(1+0.5%) -> 8562.4302 | Q15: =P15*(1+0.5%) -> 8605.2424 | R15: =Q15*(1+0.5%) -> 8648.2686 | S15: =R15*(1+0.5%) -> 8691.5099 | T15: =S15*(1+0.5%) -> 8734.9675 | U15: =T15*(1+0.5%) -> 8778.6423 | V15: =U15*(1+0.5%) -> 8822.5355
D16: Less: Depreciation | H16: =-'Financial Statements'!H62 -> -1242.62 | I16: =-'Financial Statements'!I62 -> -1148.05 | J16: =-'Financial Statements'!J62 -> -1807.98 | K16: =-'Financial Statements'!K62 -> -2908.21 | L16: =-'Financial Statements'!L62 -> -2750.2 | M16: =-M14*'Ratio Analysis & Interpretation'!M10 -> -3157.1068 | N16: =-N14*'Ratio Analysis & Interpretation'!N10 -> -3593.1096 | O16: =-O14*'Ratio Analysis & Interpretation'!O10 -> -4964.2161 | P16: =-P14*'Ratio Analysis & Interpretation'!P10 -> -5329.0402 | Q16: =-Q14*'Ratio Analysis & Interpretation'!Q10 -> -5660.8024 | R16: =-R14*'Ratio Analysis & Interpretation'!R10 -> -7125.2214 | S16: =-S14*'Ratio Analysis & Interpretation'!S10 -> -7311.9547 | T16: =-T14*'Ratio Analysis & Interpretation'!T10 -> -7481.0952 | ... V16: =-V14*'Ratio Analysis & Interpretation'!V10 -> -8865.7691
D17: PP&E Closing Balance | H17: ='Financial Statements'!H36 -> 13092.66 | I17: ='Financial Statements'!I36 -> 23090.44 | J17: ='Financial Statements'!J36 -> 26142.36 | K17: ='Financial Statements'!K36 -> 33293.48 | L17: ='Financial Statements'!L36 -> 38219.29 | M17: =SUM(M14:M16) -> 43497.451 | N17: =SUM(N14:N16) -> 48381.785 | O17: =SUM(O14:O16) -> 51937.4 | P17: =SUM(P14:P16) -> 55170.79 | Q17: =SUM(Q14:Q16) -> 58115.23 | R17: =SUM(R14:R16) -> 59638.277 | S17: =SUM(S14:S16) -> 61017.832 | T17: =SUM(T14:T16) -> 62271.705 | ... V17: =SUM(V14:V16) -> 62126.853
C19: Debt and Interest Schedule
D20: Debt Opening Balance | I20: =H22 -> 55416.12 | J20: =I22 -> 63968.33 | K20: =J22 -> 34718.35 | L20: =K22 -> 51383.83 | M20: =L22 -> 61097.96 | N20: =M22 -> 61097.96 | O20: =N22 -> 61097.96 | P20: =O22 -> 61097.96 | ... V20: =U22 -> 61097.96
D21: Issuance (Repayment) of Debt | I21: =I22-I20 -> 8552.21 | J21: =J22-J20 -> -29249.98 | K21: =K22-K20 -> 16665.48 | L21: =L22-L20 -> 9714.13 | M21: 0 | N21: 0 | O21: 0 | P21: 0 | Q21: 0 | R21: 0 | S21: 0 | T21: 0 | U21: 0 | V21: 0
D22: Debt Closing Balance | H22: ='Financial Statements'!H47 -> 55416.12 | I22: ='Financial Statements'!I47 -> 63968.33 | J22: ='Financial Statements'!J47 -> 34718.35 | K22: ='Financial Statements'!K47 -> 51383.83 | L22: ='Financial Statements'!L47 -> 61097.96 | M22: =SUM(M20:M21) -> 61097.96 | N22: =SUM(N20:N21) -> 61097.96 | O22: =SUM(O20:O21) -> 61097.96 | P22: =SUM(P20:P21) -> 61097.96 | Q22: =SUM(Q20:Q21) -> 61097.96 | R22: =SUM(R20:R21) -> 61097.96 | S22: =SUM(S20:S21) -> 61097.96 | T22: =SUM(T20:T21) -> 61097.96 | ... V22: =SUM(V20:V21) -> 61097.96
D23: Interest Expense | H23: ='Financial Statements'!H19 -> -4261.32 | I23: ='Financial Statements'!I19 -> -4353.84 | J23: ='Financial Statements'!J19 -> -4859.52 | K23: ='Financial Statements'!K19 -> -4440.26 | L23: ='Financial Statements'!L19 -> -4843.39 | M23: =-M22*'Ratio Analysis & Interpretation'!M11 -> -5753.697 | N23: =-N22*'Ratio Analysis & Interpretation'!N11 -> -5753.697 | O23: =-O22*'Ratio Analysis & Interpretation'!O11 -> -5753.697 | P23: =-P22*'Ratio Analysis & Interpretation'!P11 -> -5753.697 | Q23: =-Q22*'Ratio Analysis & Interpretation'!Q11 -> -5753.697 | R23: =-R22*'Ratio Analysis & Interpretation'!R11 -> -5753.697 | S23: =-S22*'Ratio Analysis & Interpretation'!S11 -> -5753.697 | T23: =-T22*'Ratio Analysis & Interpretation'!T11 -> -5753.697 | ... V23: =-V22*'Ratio Analysis & Interpretation'!V11 -> -5753.697

Sheet Financial Statements
A1: ='Historical Info'!A1 -> Ugar Sugar Works Ltd. | H1: Historical Info. | M1: Forecasted Info. | Y1: Interpretation of Ratios
A2: Financial Statements and DCF Analysis | H2: 2021 | I2: =H2+1 -> 2022 | J2: =I2+1 -> 2023 | K2: =J2+1 -> 2024 | L2: =K2+1 -> 2025 | M2: =L2+1 -> 2026 | N2: =M2+1 -> 2027 | O2: =N2+1 -> 2028 | P2: =O2+1 -> 2029 | ... V2: =U2+1 -> 2035 | W2: Trend
D3: Master Check | H3: =IF(H57="Perfect","Perfect","Error") -> Perfect | I3: =IF(I57="Perfect","Perfect","Error") -> Perfect | J3: =IF(J57="Perfect","Perfect","Error") -> Perfect | K3: =IF(K57="Perfect","Perfect","Error") -> Perfect | L3: =IF(L57="Perfect","Perfect","Error") -> Perfect | M3: =IF(M57="Perfect","Perfect","Error") -> Perfect | N3: =IF(N57="Perfect","Perfect","Error") -> Perfect | O3: =IF(O57="Perfect","Perfect","Error") -> Perfect | ... V3: =IF(V57="Perfect","Perfect","Error") -> Perfect
D6: LIVE SCENARIO | E6: Base Case | F6: Units | G6: =IF(E6='Rev Growth Scenarios'!D5,1,IF('Financial Statements'!E6='Rev Growth Scenarios'!D6,2,3)) -> 1
A8: Income Statement
B9: INCOME
D10: Revenue | F10: ₹ in Lakhs | H10: ='Historical Info'!H6 -> 111796.48 | I10: ='Historical Info'!I6 -> 130158.9 | J10: ='Historical Info'!J6 -> 194014.95 | K10: ='Historical Info'!K6 -> 127723.66 | L10: ='Historical Info'!L6 -> 140741.27 | M10: =L10*(1+'Ratio Analysis & Interpretation'!M6) -> 154623.95 | N10: =M10*(1+'Ratio Analysis & Interpretation'!N6) -> 168427.06 | O10: =N10*(1+'Ratio Analysis & Interpretation'!O6) -> 182034.02 | P10: =O10*(1+'Ratio Analysis & Interpretation'!P6) -> 195343.16 | Q10: =P10*(1+'Ratio Analysis & Interpretation'!Q6) -> 208268.57 | R10: =Q10*(1+'Ratio Analysis & Interpretation'!R6) -> 220740.06 | S10: =R10*(1+'Ratio Analysis & Interpretation'!S6) -> 232702.63 | T10: =S10*(1+'Ratio Analysis & Interpretation'!T6) -> 244115.45 | ... V10: =U10*(1+'Ratio Analysis & Interpretation'!V6) -> 265191.69
D11: COGS | H11: =-('Historical Info'!H10+'Historical Info'!H11+'Historical Info'!H12+'Historical Info'!H13) -> -79402.4 | I11: =-('Historical Info'!I10+'Historical Info'!I11+'Historical Info'!I12+'Historical Info'!I13) -> -92627.41 | J11: =-('Historical Info'!J10+'Historical Info'!J11+'Historical Info'!J12+'Historical Info'!J13) -> -143573.51 | K11: =-('Historical Info'!K10+'Historical Info'!K11+'Historical Info'!K12+'Historical Info'!K13) -> -94539.37 | L11: =-('Historical Info'!L10+'Historical Info'!L11+'Historical Info'!L12+'Historical Info'!L13) -> -116720.15 | M11: =-M10*'Ratio Analysis & Interpretation'!M7 -> -115393.16 | N11: =-N10*'Ratio Analysis & Interpretation'!N7 -> -125694.19 | O11: =-O10*'Ratio Analysis & Interpretation'!O7 -> -135848.82 | P11: =-P10*'Ratio Analysis & Interpretation'!P7 -> -145781.2 | Q11: =-Q10*'Ratio Analysis & Interpretation'!Q7 -> -155427.21 | R11: =-R10*'Ratio Analysis & Interpretation'!R7 -> -164734.47 | S11: =-S10*'Ratio Analysis & Interpretation'!S7 -> -173661.92 | T11: =-T10*'Ratio Analysis & Interpretation'!T7 -> -182179.11 | ... V11: =-V10*'Ratio Analysis & Interpretation'!V7 -> -197907.94
D12: Gross Profit | H12: =SUM(H10:H11) -> 32394.08 | I12: =SUM(I10:I11) -> 37531.49 | J12: =SUM(J10:J11) -> 50441.44 | K12: =SUM(K10:K11) -> 33184.29 | L12: =SUM(L10:L11) -> 24021.12 | M12: =SUM(M10:M11) -> 39230.786 | N12: =SUM(N10:N11) -> 42732.877 | O12: =SUM(O10:O11) -> 46185.197 | ... V12: =SUM(V10:V11) -> 67283.746
B13: EXPENSES
D14: Salaries & benefits | H14: =-'Historical Info'!H14 -> -6949.56 | I14: =-'Historical Info'!I14 -> -7843.89 | J14: =-'Historical Info'!J14 -> -10793.89 | K14: =-'Historical Info'!K14 -> -9452.44 | L14: =-'Historical Info'!L14 -> -8846.52 | M14: =-M10*'Ratio Analysis & Interpretation'!M8 -> -9738.9725 | N14: =-N10*'Ratio Analysis & Interpretation'!N8 -> -10608.36 | O14: =-O10*'Ratio Analysis & Interpretation'!O8 -> -11465.393 | P14: =-P10*'Ratio Analysis & Interpretation'!P8 -> -12303.667 | Q14: =-Q10*'Ratio Analysis & Interpretation'!Q8 -> -13117.773 | R14: =-R10*'Ratio Analysis & Interpretation'!R8 -> -13903.289 | S14: =-S10*'Ratio Analysis & Interpretation'!S8 -> -14656.75 | T14: =-T10*'Ratio Analysis & Interpretation'!T8 -> -15375.585 | ... V14: =-V10*'Ratio Analysis & Interpretation'!V8 -> -16703.069
D15: Other SG&A expenses | H15: =-('Historical Info'!H16+'Historical Info'!H18) -> -18666.97 | I15: =-('Historical Info'!I16+'Historical Info'!I18) -> -19773.34 | J15: =-('Historical Info'!J16+'Historical Info'!J18) -> -18783.13 | K15: =-('Historical Info'!K16+'Historical Info'!K18) -> -16711.18 | L15: =-('Historical Info'!L16+'Historical Info'!L18) -> -11131.4 | M15: =-M10*'Ratio Analysis & Interpretation'!M9 -> -19347.547 | N15: =-N10*'Ratio Analysis & Interpretation'!N9 -> -21074.682 | O15: =-O10*'Ratio Analysis & Interpretation'!O9 -> -22777.272 | P15: =-P10*'Ratio Analysis & Interpretation'!P9 -> -24442.598 | Q15: =-Q10*'Ratio Analysis & Interpretation'!Q9 -> -26059.909 | R15: =-R10*'Ratio Analysis & Interpretation'!R9 -> -27620.422 | S15: =-S10*'Ratio Analysis & Interpretation'!S9 -> -29117.256 | T15: =-T10*'Ratio Analysis & Interpretation'!T9 -> -30545.303 | ... V15: =-V10*'Ratio Analysis & Interpretation'!V9 -> -33182.497 | Y15: Other SG&A expenses
D16: EBITDA | H16: =SUM(H12,H14:H15) -> 6777.55 | I16: =SUM(I12,I14:I15) -> 9914.26 | J16: =SUM(J12,J14:J15) -> 20864.42 | K16: =SUM(K12,K14:K15) -> 7020.67 | L16: =SUM(L12,L14:L15) -> 4043.2 | M16: =SUM(M12,M14:M15) -> 10144.267 | N16: =SUM(N12,N14:N15) -> 11049.834 | O16: =SUM(O12,O14:O15) -> 11942.533 | ... V16: =SUM(V12,V14:V15) -> 17398.179 | Y16: Depreciation & Amortization expenses
D17: Depreciation & Amortization expenses | H17: =-'Historical Info'!H17 -> -1242.62 | I17: =-'Historical Info'!I17 -> -1148.05 | J17: =-'Historical Info'!J17 -> -1807.97 | K17: =-'Historical Info'!K17 -> -2908.21 | L17: =-'Historical Info'!L17 -> -2750.21 | M17: ='Working Schedules'!M16 -> -3157.1068 | N17: ='Working Schedules'!N16 -> -3593.1096 | O17: ='Working Schedules'!O16 -> -4964.2161 | P17: ='Working Schedules'!P16 -> -5329.0402 | Q17: ='Working Schedules'!Q16 -> -5660.8024 | R17: ='Working Schedules'!R16 -> -7125.2214 | S17: ='Working Schedules'!S16 -> -7311.9547 | T17: ='Working Schedules'!T16 -> -7481.0952 | ... V17: ='Working Schedules'!V16 -> -8865.7691 | Y17: Interest
D18: EBIT | H18: =SUM(H16:H17) -> 5534.93 | I18: =SUM(I16:I17) -> 8766.21 | J18: =SUM(J16:J17) -> 19056.45 | K18: =SUM(K16:K17) -> 4112.46 | L18: =SUM(L16:L17) -> 1292.99 | M18: =SUM(M16:M17) -> 6987.1597 | N18: =SUM(N16:N17) -> 7456.7248 | O18: =SUM(O16:O17) -> 6978.3167 | ... V18: =SUM(V16:V17) -> 8532.41 | Y18: Other Income (Expenses)
D19: Interest | H19: =-'Historical Info'!H15 -> -4261.32 | I19: =-'Historical Info'!I15 -> -4353.84 | J19: =-'Historical Info'!J15 -> -4859.52 | K19: =-'Historical Info'!K15 -> -4440.26 | L19: =-'Historical Info'!L15 -> -4843.39 | M19: ='Working Schedules'!M23 -> -5753.697 | N19: ='Working Schedules'!N23 -> -5753.697 | O19: ='Working Schedules'!O23 -> -5753.697 | P19: ='Working Schedules'!P23 -> -5753.697 | Q19: ='Working Schedules'!Q23 -> -5753.697 | R19: ='Working Schedules'!R23 -> -5753.697 | S19: ='Working Schedules'!S23 -> -5753.697 | T19: ='Working Schedules'!T23 -> -5753.697 | ... V19: ='Working Schedules'!V23 -> -5753.697 | Y19: Taxes
D20: Other Income (Expenses) | H20: ='Historical Info'!H7 -> 586.52 | I20: ='Historical Info'!I7 -> 224.47 | J20: ='Historical Info'!J7 -> 642.31 | K20: ='Historical Info'!K7 -> 3307.94 | L20: ='Historical Info'!L7 -> 1339.29 | M20: =M10*'Ratio Analysis & Interpretation'!M12 -> 1413.1606 | N20: =N10*'Ratio Analysis & Interpretation'!N12 -> 1539.3119 | O20: =O10*'Ratio Analysis & Interpretation'!O12 -> 1663.6705 | P20: =P10*'Ratio Analysis & Interpretation'!P12 -> 1785.3072 | Q20: =Q10*'Ratio Analysis & Interpretation'!Q12 -> 1903.4369 | R20: =R10*'Ratio Analysis & Interpretation'!R12 -> 2017.4181 | S20: =S10*'Ratio Analysis & Interpretation'!S12 -> 2126.7481 | T20: =T10*'Ratio Analysis & Interpretation'!T12 -> 2231.0537 | ... V20: =V10*'Ratio Analysis & Interpretation'!V12 -> 2423.6765
D21: Earnings before Tax | H21: =SUM(H18:H20) -> 1860.13 | I21: =SUM(I18:I20) -> 4636.84 | J21: =SUM(J18:J20) -> 14839.24 | K21: =SUM(K18:K20) -> 2980.14 | L21: =SUM(L18:L20) -> -2211.11 | M21: =SUM(M18:M20) -> 2646.6233 | N21: =SUM(N18:N20) -> 3242.3398 | O21: =SUM(O18:O20) -> 2888.2902 | ... V21: =SUM(V18:V20) -> 5202.3896
D22: Taxes | H22: =-'Historical Info'!H28 -> -155.07 | I22: =-'Historical Info'!I28 -> -304 | J22: =-'Historical Info'!J28 -> -4534.44 | K22: =-'Historical Info'!K28 -> -865.89 | L22: =-'Historical Info'!L28 -> 586.16 | M22: =-M21*'Ratio Analysis & Interpretation'!M13 -> -714.84667 | N22: =-N21*'Ratio Analysis & Interpretation'!N13 -> -875.74827 | O22: =-O21*'Ratio Analysis & Interpretation'!O13 -> -794.56177 | P22: =-P21*'Ratio Analysis & Interpretation'!P13 -> -967.86583 | Q22: =-Q21*'Ratio Analysis & Interpretation'!Q13 -> -1163.1378 | R22: =-R21*'Ratio Analysis & Interpretation'!R13 -> -1014.0607 | S22: =-S21*'Ratio Analysis & Interpretation'!S13 -> -1233.8446 | T22: =-T21*'Ratio Analysis & Interpretation'!T13 -> -1428.8273 | ... V22: =-V21*'Ratio Analysis & Interpretation'!V13 -> -1509.2009
D23: Net Earnings (PAT) | H23: =SUM(H21:H22) -> 1705.06 | I23: =SUM(I21:I22) -> 4332.84 | J23: =SUM(J21:J22) -> 10304.8 | K23: =SUM(K21:K22) -> 2114.25 | L23: =SUM(L21:L22) -> -1624.95 | M23: =SUM(M21:M22) -> 1931.7767 | N23: =SUM(N21:N22) -> 2366.5915 | O23: =SUM(O21:O22) -> 2093.7285 | ... V23: =SUM(V21:V22) -> 3693.1888
A26: Balance Sheet
B27: ASSETS
C28: Current Assets | F28: =F10 -> ₹ in Lakhs
D29: Cash | H29: ='Historical Info'!H50 -> 542.09 | I29: ='Historical Info'!I50 -> 624.26 | J29: ='Historical Info'!J50 -> 576.05 | K29: ='Historical Info'!K50 -> 93.84 | L29: ='Historical Info'!L50 -> 168.78 | M29: =M84 -> -10279.713 | N29: =N84 -> -18374.392 | O29: =O84 -> -25309.36 | P29: =P84 -> -31397.312 | Q29: =Q84 -> -36654.099 | R29: =R84 -> -40657.858 | S29: =S84 -> -43883.979 | T29: =T84 -> -46333.328 | ... V29: =V84 -> -48202.289
D30: Bank Deposits | H30: ='Historical Info'!H51 -> 128.69 | I30: ='Historical Info'!I51 -> 146.39 | J30: ='Historical Info'!J51 -> 1260.95 | K30: ='Historical Info'!K51 -> 3968.06 | L30: ='Historical Info'!L51 -> 1724.5 | M30: =L30 -> 1724.5 | N30: =M30 -> 1724.5 | O30: =N30 -> 1724.5 | P30: =O30 -> 1724.5 | Q30: =P30 -> 1724.5 | R30: =Q30 -> 1724.5 | S30: =R30 -> 1724.5 | T30: =S30 -> 1724.5 | ... V30: =U30 -> 1724.5
D31: Account Receivables | H31: ='Historical Info'!H49 -> 4933.93 | I31: ='Historical Info'!I49 -> 8887.46 | J31: ='Historical Info'!J49 -> 18730.41 | K31: ='Historical Info'!K49 -> 14209.78 | L31: ='Historical Info'!L49 -> 12042.87 | M31: =(M10*'Ratio Analysis & Interpretation'!M15)/365 -> 12548.579 | N31: =N10*'Ratio Analysis & Interpretation'!N15/365 -> 13668.778 | O31: =O10*'Ratio Analysis & Interpretation'!O15/365 -> 14773.056 | P31: =P10*'Ratio Analysis & Interpretation'!P15/365 -> 15853.166 | Q31: =Q10*'Ratio Analysis & Interpretation'!Q15/365 -> 16902.134 | R31: =R10*'Ratio Analysis & Interpretation'!R15/365 -> 17914.264 | S31: =S10*'Ratio Analysis & Interpretation'!S15/365 -> 18885.091 | T31: =T10*'Ratio Analysis & Interpretation'!T15/365 -> 19811.305 | U31: =U10*'Ratio Analysis & Interpretation'!U15/365 -> 20690.638 | V31: =V10*'Ratio Analysis & Interpretation'!V15/365 -> 21521.756
D32: Inventory | H32: ='Historical Info'!H47 -> 63511.28 | I32: ='Historical Info'!I47 -> 76948.56 | J32: ='Historical Info'!J47 -> 36530.42 | K32: ='Historical Info'!K47 -> 48506.78 | L32: ='Historical Info'!L47 -> 52631.9 | M32: =-M11*'Ratio Analysis & Interpretation'!M16/365 -> 65752.05 | N32: =-N11*'Ratio Analysis & Interpretation'!N16/365 -> 71621.666 | O32: =-O11*'Ratio Analysis & Interpretation'!O16/365 -> 77407.865 | P32: =-P11*'Ratio Analysis & Interpretation'!P16/365 -> 83067.424 | Q32: =-Q11*'Ratio Analysis & Interpretation'!Q16/365 -> 88563.805 | R32: =-R11*'Ratio Analysis & Interpretation'!R16/365 -> 93867.164 | S32: =-S11*'Ratio Analysis & Interpretation'!S16/365 -> 98954.108 | T32: =-T11*'Ratio Analysis & Interpretation'!T16/365 -> 103807.28 | ... V32: =-V11*'Ratio Analysis & Interpretation'!V16/365 -> 112769.7
D33: Other Current Assets | H33: ='Historical Info'!H52+'Historical Info'!H53+'Historical Info'!H54 -> 6422.28 | I33: ='Historical Info'!I52+'Historical Info'!I53+'Historical Info'!I54 -> 5675.46 | J33: ='Historical Info'!J52+'Historical Info'!J53+'Historical Info'!J54 -> 6353.26 | K33: ='Historical Info'!K52+'Historical Info'!K53+'Historical Info'!K54 -> 6207.65 | L33: ='Historical Info'!L52+'Historical Info'!L53+'Historical Info'!L54 -> 5807.37 | M33: =L33 -> 5807.37 | N33: =M33 -> 5807.37 | O33: =N33 -> 5807.37 | P33: =O33 -> 5807.37 | Q33: =P33 -> 5807.37 | R33: =Q33 -> 5807.37 | S33: =R33 -> 5807.37 | T33: =S33 -> 5807.37 | ... V33: =U33 -> 5807.37
C35: Non-current Assets
D36: Property, Plant & Equipments | H36: ='Historical Info'!H37+'Historical Info'!H38 -> 13092.66 | I36: ='Historical Info'!I37+'Historical Info'!I38 -> 23090.44 | J36: ='Historical Info'!J37+'Historical Info'!J38 -> 26142.36 | K36: ='Historical Info'!K37+'Historical Info'!K38 -> 33293.48 | L36: ='Historical Info'!L37+'Historical Info'!L38 -> 38219.29 | M36: ='Working Schedules'!M17 -> 43497.451 | N36: ='Working Schedules'!N17 -> 48381.785 | O36: ='Working Schedules'!O17 -> 51937.4 | P36: ='Working Schedules'!P17 -> 55170.79 | Q36: ='Working Schedules'!Q17 -> 58115.23 | R36: ='Working Schedules'!R17 -> 59638.277 | S36: ='Working Schedules'!S17 -> 61017.832 | T36: ='Working Schedules'!T17 -> 62271.705 | ... V36: ='Working Schedules'!V17 -> 62126.853
D37: Goodwill | H37: ='Historical Info'!H41 -> 2.8 | I37: ='Historical Info'!I41 -> 2.52 | J37: ='Historical Info'!J41 -> 9.1 | K37: ='Historical Info'!K41 -> 7.65 | L37: ='Historical Info'!L41 -> 3.52 | M37: =L37 -> 3.52 | N37: =M37 -> 3.52 | O37: =N37 -> 3.52 | P37: =O37 -> 3.52 | Q37: =P37 -> 3.52 | R37: =Q37 -> 3.52 | S37: =R37 -> 3.52 | T37: =S37 -> 3.52 | ... V37: =U37 -> 3.52
D38: Financial Assets | H38: =SUM('Historical Info'!H43,'Historical Info'!H44,'Historical Info'!H39) -> 382.91 | I38: =SUM('Historical Info'!I43,'Historical Info'!I44,'Historical Info'!I39) -> 377.59 | J38: =SUM('Historical Info'!J43,'Historical Info'!J44,'Historical Info'!J39) -> 365.27 | K38: =SUM('Historical Info'!K43,'Historical Info'!K44,'Historical Info'!K39) -> 359.9 | L38: =SUM('Historical Info'!L43,'Historical Info'!L44,'Historical Info'!L39) -> 514.5 | M38: =L38 -> 514.5 | N38: =M38 -> 514.5 | O38: =N38 -> 514.5 | P38: =O38 -> 514.5 | Q38: =P38 -> 514.5 | R38: =Q38 -> 514.5 | S38: =R38 -> 514.5 | T38: =S38 -> 514.5 | ... V38: =U38 -> 514.5
D39: Other Non-Current Assets | H39: ='Historical Info'!H45 -> 326.1 | I39: ='Historical Info'!I45 -> 612.13 | J39: ='Historical Info'!J45 -> 1670.12 | K39: ='Historical Info'!K45 -> 1877.94 | L39: ='Historical Info'!L45 -> 1949.93 | M39: =L39 -> 1949.93 | N39: =M39 -> 1949.93 | O39: =N39 -> 1949.93 | P39: =O39 -> 1949.93 | Q39: =P39 -> 1949.93 | R39: =Q39 -> 1949.93 | S39: =R39 -> 1949.93 | T39: =S39 -> 1949.93 | ... V39: =U39 -> 1949.93
D40: Total Assets | H40: =SUM(H29:H33,H36:H39) -> 89342.74 | I40: =SUM(I29:I33,I36:I39) -> 116364.81 | J40: =SUM(J29:J33,J36:J39) -> 91637.94 | K40: =SUM(K29:K33,K36:K39) -> 108525.08 | L40: =SUM(L29:L33,L36:L39) -> 113062.66 | M40: =SUM(M29:M33,M36:M39) -> 121518.19 | N40: =SUM(N29:N33,N36:N39) -> 125297.66 | O40: =SUM(O29:O33,O36:O39) -> 128808.78 | ... V40: =SUM(V29:V33,V36:V39) -> 158215.85
B42: LIABILITIES
C43: Current Liabilities
D44: Account Payables | H44: =SUM('Historical Info'!H73,'Historical Info'!H74,'Historical Info'!H75,'Historical Info'!H76,'Historical Info'!H77) -> 11749.81 | I44: =SUM('Historical Info'!I73,'Historical Info'!I74,'Historical Info'!I75,'Historical Info'!I76,'Historical Info'!I77) -> 23169.03 | J44: =SUM('Historical Info'!J73,'Historical Info'!J74,'Historical Info'!J75,'Historical Info'!J76,'Historical Info'!J77) -> 15611.66 | K44: =SUM('Historical Info'!K73,'Historical Info'!K74,'Historical Info'!K75,'Historical Info'!K76,'Historical Info'!K77) -> 18500.87 | L44: =SUM('Historical Info'!L73,'Historical Info'!L74,'Historical Info'!L75,'Historical Info'!L76,'Historical Info'!L77) -> 11830.52 | M44: =-M11*'Ratio Analysis & Interpretation'!M17/365 -> 18552.883 | N44: =-N11*'Ratio Analysis & Interpretation'!N17/365 -> 20209.079 | O44: =-O11*'Ratio Analysis & Interpretation'!O17/365 -> 21841.738 | P44: =-P11*'Ratio Analysis & Interpretation'!P17/365 -> 23438.664 | Q44: =-Q11*'Ratio Analysis & Interpretation'!Q17/365 -> 24989.546 | R44: =-R11*'Ratio Analysis & Interpretation'!R17/365 -> 26485.965 | S44: =-S11*'Ratio Analysis & Interpretation'!S17/365 -> 27921.319 | T44: =-T11*'Ratio Analysis & Interpretation'!T17/365 -> 29290.711 | ... V44: =-V11*'Ratio Analysis & Interpretation'!V17/365 -> 31819.587
D45: Other Current Liabilities | H45: =SUM('Historical Info'!H78,'Historical Info'!H79,'Historical Info'!H80,'Historical Info'!H81) -> 12820.8 | I45: =SUM('Historical Info'!I78,'Historical Info'!I79,'Historical Info'!I80,'Historical Info'!I81) -> 15760.04 | J45: =SUM('Historical Info'!J78,'Historical Info'!J79,'Historical Info'!J80,'Historical Info'!J81) -> 17791.8 | K45: =SUM('Historical Info'!K78,'Historical Info'!K79,'Historical Info'!K80,'Historical Info'!K81) -> 13728.77 | L45: =SUM('Historical Info'!L78,'Historical Info'!L79,'Historical Info'!L80,'Historical Info'!L81) -> 17681.41 | M45: =L45 -> 17681.41 | N45: =M45 -> 17681.41 | O45: =N45 -> 17681.41 | P45: =O45 -> 17681.41 | Q45: =P45 -> 17681.41 | R45: =Q45 -> 17681.41 | S45: =R45 -> 17681.41 | T45: =S45 -> 17681.41 | ... V45: =U45 -> 17681.41
C46: Non-Current Liabilities
D47: Debt | H47: ='Historical Info'!H66+'Historical Info'!H71 -> 55416.12 | I47: ='Historical Info'!I66+'Historical Info'!I71 -> 63968.33 | J47: ='Historical Info'!J66+'Historical Info'!J71 -> 34718.35 | K47: ='Historical Info'!K66+'Historical Info'!K71 -> 51383.83 | L47: ='Historical Info'!L66+'Historical Info'!L71 -> 61097.96 | M47: ='Working Schedules'!M22 -> 61097.96 | N47: ='Working Schedules'!N22 -> 61097.96 | O47: ='Working Schedules'!O22 -> 61097.96 | P47: ='Working Schedules'!P22 -> 61097.96 | Q47: ='Working Schedules'!Q22 -> 61097.96 | R47: ='Working Schedules'!R22 -> 61097.96 | S47: ='Working Schedules'!S22 -> 61097.96 | T47: ='Working Schedules'!T22 -> 61097.96 | ... V47: ='Working Schedules'!V22 -> 61097.96
...

Sheet DCF
A1: ='Historical Info'!A1 -> Ugar Sugar Works Ltd.
A2: Revenue Growth Scenarios
A4: DCF Analysis
D6: Assumptions
D7: Transaction date | E7: 46064
D8: Fiscal Year end | E8: =EOMONTH(E7,1) -> 46112
D9: Tax rate | E9: ='Comps (Data)'!K11 -> 0.27409762
D10: EV/EBITDA multiple | E10: ='Comps Valuation'!S20 -> 11.463405
D11: Perpetual Growth Rate | E11: 0.04
D12: Discount Rate (WACC) | E12: =WACC!H43 -> 0.076468305
D13: Shares Outstanding | E13: ='Comps (Data)'!D11 -> 1125.3063
D14: Current Market Price | E14: ='Comps Valuation'!H20 -> 39.33
A17: Unlevered Free Cash Flow
H18: Historical FCFF | M18: DCF- FCFF
D19: Discounted Cash Flow | H19: ='Financial Statements'!H2 -> 2021 | I19: ='Financial Statements'!I2 -> 2022 | J19: ='Financial Statements'!J2 -> 2023 | K19: ='Financial Statements'!K2 -> 2024 | L19: ='Financial Statements'!L2 -> 2025 | M19: Entry Date | N19: ='Financial Statements'!M2 -> 2026 | O19: ='Financial Statements'!N2 -> 2027 | P19: ='Financial Statements'!O2 -> 2028 | Q19: ='Financial Statements'!P2 -> 2029 | R19: ='Financial Statements'!Q2 -> 2030 | S19: ='Financial Statements'!R2 -> 2031 | T19: ='Financial Statements'!S2 -> 2032 | U19: ='Financial Statements'!T2 -> 2033 | ... W19: ='Financial Statements'!V2 -> 2035 | X19: Exit
D20: Date | M20: =E7 -> 46064 | N20: =DATE(YEAR($M$20)+N21,MONTH($E$8),DAY($E$8)) -> 46112 | O20: =DATE(YEAR($M$20)+O21,MONTH($E$8),DAY($E$8)) -> 46477 | P20: =DATE(YEAR($M$20)+P21,MONTH($E$8),DAY($E$8)) -> 46843 | Q20: =DATE(YEAR($M$20)+Q21,MONTH($E$8),DAY($E$8)) -> 47208 | R20: =DATE(YEAR($M$20)+R21,MONTH($E$8),DAY($E$8)) -> 47573 | S20: =DATE(YEAR($M$20)+S21,MONTH($E$8),DAY($E$8)) -> 47938 | T20: =DATE(YEAR($M$20)+T21,MONTH($E$8),DAY($E$8)) -> 48304 | U20: =DATE(YEAR($M$20)+U21,MONTH($E$8),DAY($E$8)) -> 48669 | ... W20: =DATE(YEAR($M$20)+W21,MONTH($E$8),DAY($E$8)) -> 49399 | X20: =W20 -> 49399
D21: Time period | N21: 0 | O21: =N21+1 -> 1 | P21: =O21+1 -> 2 | Q21: =P21+1 -> 3 | R21: =Q21+1 -> 4 | S21: =R21+1 -> 5 | T21: =S21+1 -> 6 | U21: =T21+1 -> 7 | V21: =U21+1 -> 8 | W21: =V21+1 -> 9
D22: Yearfrac | N22: =YEARFRAC(M20,N20) -> 0.13888889 | O22: =YEARFRAC(N20,O20) -> 1 | P22: =YEARFRAC(O20,P20) -> 1 | Q22: =YEARFRAC(P20,Q20) -> 1 | R22: =YEARFRAC(Q20,R20) -> 1 | S22: =YEARFRAC(R20,S20) -> 1 | T22: =YEARFRAC(S20,T20) -> 1 | U22: =YEARFRAC(T20,U20) -> 1 | ... W22: =YEARFRAC(V20,W20) -> 1 | X22: =W22 -> 1
D24: EBIT | I24: ='Financial Statements'!I18 -> 8766.21 | J24: ='Financial Statements'!J18 -> 19056.45 | K24: ='Financial Statements'!K18 -> 4112.46 | L24: ='Financial Statements'!L18 -> 1292.99 | N24: ='Financial Statements'!M18 -> 6987.1597 | O24: ='Financial Statements'!N18 -> 7456.7248 | P24: ='Financial Statements'!O18 -> 6978.3167 | Q24: ='Financial Statements'!P18 -> 7486.6529 | R24: ='Financial Statements'!Q18 -> 8002.8758 | S24: ='Financial Statements'!R18 -> 7356.6621 | T24: ='Financial Statements'!S18 -> 7954.7457 | U24: ='Financial Statements'!T18 -> 8534.3556 | ... W24: ='Financial Statements'!V18 -> 8532.41
D25: Less: Cash Tax | I25: ='Financial Statements'!I22 -> -304 | J25: ='Financial Statements'!J22 -> -4534.44 | K25: ='Financial Statements'!K22 -> -865.89 | L25: ='Financial Statements'!L22 -> 586.16 | N25: ='Financial Statements'!M22 -> -714.84667 | O25: ='Financial Statements'!N22 -> -875.74827 | P25: ='Financial Statements'!O22 -> -794.56177 | Q25: ='Financial Statements'!P22 -> -967.86583 | R25: ='Financial Statements'!Q22 -> -1163.1378 | S25: ='Financial Statements'!R22 -> -1014.0607 | T25: ='Financial Statements'!S22 -> -1233.8446 | U25: ='Financial Statements'!T22 -> -1428.8273 | ... W25: ='Financial Statements'!V22 -> -1509.2009
D26: NOPAT | I26: =SUM(I24:I25) -> 8462.21 | J26: =SUM(J24:J25) -> 14522.01 | K26: =SUM(K24:K25) -> 3246.57 | L26: =SUM(L24:L25) -> 1879.15 | N26: =SUM(N24:N25) -> 6272.313 | O26: =SUM(O24:O25) -> 6580.9766 | P26: =SUM(P24:P25) -> 6183.755 | Q26: =SUM(Q24:Q25) -> 6518.7871 | R26: =SUM(R24:R25) -> 6839.738 | S26: =SUM(S24:S25) -> 6342.6014 | T26: =SUM(T24:T25) -> 6720.9011 | U26: =SUM(U24:U25) -> 7105.5283 | ... W26: =SUM(W24:W25) -> 7023.2092
D27: Plus: D&A | I27: =-'Financial Statements'!I17 -> 1148.05 | J27: =-'Financial Statements'!J17 -> 1807.97 | K27: =-'Financial Statements'!K17 -> 2908.21 | L27: =-'Financial Statements'!L17 -> 2750.21 | N27: =-'Financial Statements'!M17 -> 3157.1068 | O27: =-'Financial Statements'!N17 -> 3593.1096 | P27: =-'Financial Statements'!O17 -> 4964.2161 | Q27: =-'Financial Statements'!P17 -> 5329.0402 | R27: =-'Financial Statements'!Q17 -> 5660.8024 | S27: =-'Financial Statements'!R17 -> 7125.2214 | T27: =-'Financial Statements'!S17 -> 7311.9547 | U27: =-'Financial Statements'!T17 -> 7481.0952 | ... W27: =-'Financial Statements'!V17 -> 8865.7691
D28: Less: Capex | I28: =-'Working Schedules'!I15 -> -11145.83 | J28: =-'Working Schedules'!J15 -> -4859.9 | K28: =-'Working Schedules'!K15 -> -10059.33 | L28: =-'Working Schedules'!L15 -> -7676.01 | N28: =-'Working Schedules'!M15 -> -8435.2675 | O28: =-'Working Schedules'!N15 -> -8477.4438 | P28: =-'Working Schedules'!O15 -> -8519.8311 | Q28: =-'Working Schedules'!P15 -> -8562.4302 | R28: =-'Working Schedules'!Q15 -> -8605.2424 | S28: =-'Working Schedules'!R15 -> -8648.2686 | T28: =-'Working Schedules'!S15 -> -8691.5099 | U28: =-'Working Schedules'!T15 -> -8734.9675 | ... W28: =-'Working Schedules'!V15 -> -8822.5355
D29: Less: Changes in Net WC | I29: ='Working Schedules'!I11 -> -814.43 | J29: ='Working Schedules'!J11 -> 20779.29 | K29: ='Working Schedules'!K11 -> -12032.74 | L29: ='Working Schedules'!L11 -> -2824.66 | N29: ='Working Schedules'!M11 -> -6903.4966 | O29: ='Working Schedules'!N11 -> -5333.618 | P29: ='Working Schedules'!O11 -> -5257.8187 | Q29: ='Working Schedules'!P11 -> -5142.7434 | R29: ='Working Schedules'!Q11 -> -4994.4663 | S29: ='Working Schedules'!R11 -> -4819.0695 | T29: ='Working Schedules'!S11 -> -4622.4178 | U29: ='Working Schedules'!T11 -> -4409.9931 | ... W29: ='Working Schedules'!V11 -> -3957.2169
D30: Unlevered Free Cash Flow | I30: =SUM(I26:I29) -> -2350 | J30: =SUM(J26:J29) -> 32249.37 | K30: =SUM(K26:K29) -> -15937.29 | L30: =SUM(L26:L29) -> -5871.31 | M30: 0 | N30: =SUM(N26:N29) -> -5909.3443 | O30: =SUM(O26:O29) -> -3636.9756 | P30: =SUM(P26:P29) -> -2629.6787 | Q30: =SUM(Q26:Q29) -> -1857.3463 | R30: =SUM(R26:R29) -> -1099.1683 | S30: =SUM(S26:S29) -> 0.4846723 | T30: =SUM(T26:T29) -> 718.92808 | U30: =SUM(U26:U29) -> 1441.6629 | ... W30: =SUM(W26:W29) -> 3109.2259 | X30: =S39 -> 144055.51
D32: Transaction Cash flow | M32: =M30 -> 0 | N32: =N30*N22 -> -820.74226 | O32: =O30*O22 -> -3636.9756 | P32: =P30*P22 -> -2629.6787 | Q32: =Q30*Q22 -> -1857.3463 | R32: =R30*R22 -> -1099.1683 | S32: =S30*S22 -> 0.4846723 | T32: =T30*T22 -> 718.92808 | U32: =U30*U22 -> 1441.6629 | ... X32: =X30*X22 -> 144055.51
D35: Intrinsic Value (Using Implied Value) | I35: Market Value (Using Facts) | M35: Rate of Return
D36: Enterprise Value | E36: =SUM(M32:X32) -> 141759.84 | I36: Market Cap | K36: =E13*E14 -> 44258.298 | M36: Current Price | O36: =K42 -> 39.33 | Q36: Terminal Value
D37: Plus: Cash & Cash Equivalents (Including Fin Assets) | E37: =SUM('Financial Statements'!L29:L30,'Financial Statements'!L38) -> 2407.78 | I37: Less: Cash | K37: =-E37 -> -2407.78 | M37: Target Price | O37: =E42 -> 73.819597 | Q37: EV/EBITDA | S37: =(W24+W27)*E10 -> 199442.38
D38: Less: Debt | E38: =-'Working Schedules'!L22 -> -61097.96 | I38: Plus: Debt | K38: =-E38 -> 61097.96 | M38: Target Potential | O38: =O37/O36-1 -> 0.87692847 | Q38: Perpetual Growth | S38: =W30*(1+E11)/(E12-E11) -> 88668.637
D39: Less: Non- Controlling Interest | E39: ='Financial Statements'!L54 -> 0 | I39: Plus: NCI | K39: =E39 -> 0 | Q39: Average | S39: =AVERAGE(S37:S38) -> 144055.51
D40: Equity Value | E40: =SUM(E36:E39) -> 83069.66 | I40: Enterprise Value | K40: =SUM(K36:K39) -> 102948.48
D42: Equity Value per share | E42: =E40/E13 -> 73.819597 | I42: Equity Value per share | K42: =K36/E13 -> 39.33
D43: (Target Price) | I43: (Market Price)
A47: Sensitivity Analysis
H49: Sensitivities - Intrinsic values (Rs. /Share)
J51: Exit Multiple
I52: =E42 -> 73.819597 | J52: 5 | K52: 10 | L52: 11.463405 | M52: 15 | N52: 20
H53: Discount Rate | I53: 0.05 | J53: 128.13342 | K53: 166.78551 | L53: 178.09825 | M53: 205.43761 | N53: 244.0897
I54: 0.06 | J54: 56.295314 | K54: 94.947409 | L54: 106.26014 | M54: 133.5995 | N54: 172.2516
...

Sheet Comps Valuation
A1: ='Historical Info'!A1 -> Ugar Sugar Works Ltd.
A2: Comps Valuation- Values are in INR Lakhs
J5: Market Data | O5: Financial Data | S5: Valuation Metrices
H6: Price | I6: Shares | J6: Market Cap | K6: Debt | L6: Cash & Cash Equivalents | M6: Enterprise Value | N6: Sales | O6: EBITDA | P6: Earnings | Q6: Effective Tax Rate | R6: EV/Sales | S6: EV/ EBITDA | T6: P/E
D7: Company Name | F7: Ticker | H7: ₹/Share | I7: In Lakhs | J7: ₹ in Lakhs | M7: ₹ in Lakhs | N7: ₹ in Lakhs | O7: ₹ in Lakhs | P7: ₹ in Lakhs | R7: x | S7: x | T7: x
D8: ='Comps (Data)'!A2 -> Mawana Sugars Limited | F8: ='Comps (Data)'!B2 -> 523371 | H8: ='Comps (Data)'!C2 -> 79.5 | I8: ='Comps (Data)'!D2 -> 390.99666 | J8: ='Comps (Data)'!E2 -> 31097.907 | K8: ='Comps (Data)'!F2 -> 19559.408 | L8: ='Comps (Data)'!G2 -> 1521.7 | M8: =J8+K8-L8 -> 49135.615 | N8: ='Comps (Data)'!H2 -> 152953.44 | O8: ='Comps (Data)'!I2 -> 12085.844 | P8: ='Comps (Data)'!J2 -> 10172.867 | Q8: ='Comps (Data)'!K2 -> 0.164934 | R8: =M8/N8 -> 0.32124558 | S8: =M8/O8 -> 4.0655511 | T8: =J8/P8 -> 3.0569463
D9: ='Comps (Data)'!A3 -> DCM Shriram Industries Limited | F9: ='Comps (Data)'!B3 -> 523369 | H9: ='Comps (Data)'!C3 -> 37.59 | I9: ='Comps (Data)'!D3 -> 869.54098 | J9: ='Comps (Data)'!E3 -> 32700.362 | K9: ='Comps (Data)'!F3 -> 57177.206 | L9: ='Comps (Data)'!G3 -> 11028.9 | M9: =J9+K9-L9 -> 78848.668 | N9: ='Comps (Data)'!H3 -> 213747.05 | O9: ='Comps (Data)'!I3 -> 18989.116 | P9: ='Comps (Data)'!J3 -> 9313.5687 | Q9: ='Comps (Data)'!K3 -> 0.354496 | R9: =M9/N9 -> 0.36888775 | S9: =M9/O9 -> 4.1523086 | T9: =J9/P9 -> 3.5110454
D10: ='Comps (Data)'!A4 -> Magadh Sugar & Energy Limited | F10: ='Comps (Data)'!B4 -> MAGADSUGAR | H10: ='Comps (Data)'!C4 -> 417.8 | I10: ='Comps (Data)'!D4 -> 140.44682 | J10: ='Comps (Data)'!E4 -> 58874.83 | K10: ='Comps (Data)'!F4 -> 75737.668 | L10: ='Comps (Data)'!G4 -> 133.5 | M10: =J10+K10-L10 -> 134479 | N10: ='Comps (Data)'!H4 -> 138761.06 | O10: ='Comps (Data)'!I4 -> 20908.76 | P10: ='Comps (Data)'!J4 -> 10519.333 | Q10: ='Comps (Data)'!K4 -> 0.256562 | R10: =M10/N10 -> 0.96914079 | S10: =M10/O10 -> 6.431706 | T10: =J10/P10 -> 5.5968216
D11: ='Comps (Data)'!A5 -> Dwarikesh Sugar Industries Limited | F11: ='Comps (Data)'!B5 -> 532610 | H11: ='Comps (Data)'!C5 -> 33.33 | I11: ='Comps (Data)'!D5 -> 1846.9899 | J11: ='Comps (Data)'!E5 -> 61760.98 | K11: ='Comps (Data)'!F5 -> 54311.716 | L11: ='Comps (Data)'!G5 -> 29261.02 | M11: =J11+K11-L11 -> 86811.675 | N11: ='Comps (Data)'!H5 -> 152377.14 | O11: ='Comps (Data)'!I5 -> 11954.825 | P11: ='Comps (Data)'!J5 -> 2535.2519 | Q11: ='Comps (Data)'!K5 -> 0.564909 | R11: =M11/N11 -> 0.56971588 | S11: =M11/O11 -> 7.2616436 | T11: =J11/P11 -> 24.360885
D12: ='Comps (Data)'!A6 -> Avadh Sugar & Energy Limited | F12: ='Comps (Data)'!B6 -> AVADHSUGAR | H12: ='Comps (Data)'!C6 -> 322.35 | I12: ='Comps (Data)'!D6 -> 200.22026 | J12: ='Comps (Data)'!E6 -> 64529.377 | K12: ='Comps (Data)'!F6 -> 146798.27 | L12: ='Comps (Data)'!G6 -> 372.8 | M12: =J12+K12-L12 -> 210954.84 | N12: ='Comps (Data)'!H6 -> 283126.79 | O12: ='Comps (Data)'!I6 -> 26403.179 | P12: ='Comps (Data)'!J6 -> 7584.426 | Q12: ='Comps (Data)'!K6 -> 0.35483 | R12: =M12/N12 -> 0.74508967 | S12: =M12/O12 -> 7.9897517 | T12: =J12/P12 -> 8.5081425
D13: ='Comps (Data)'!A7 -> Davangere Sugar Company Limited | F13: ='Comps (Data)'!B7 -> DAVANGERE | H13: ='Comps (Data)'!C7 -> 4.59 | I13: ='Comps (Data)'!D7 -> 7290.8429 | J13: ='Comps (Data)'!E7 -> 46392.038 | K13: ='Comps (Data)'!F7 -> 38172.128 | L13: ='Comps (Data)'!G7 -> 1220.1 | M13: =J13+K13-L13 -> 83344.065 | N13: ='Comps (Data)'!H7 -> 20717.142 | O13: ='Comps (Data)'!I7 -> 5768.9815 | P13: ='Comps (Data)'!J7 -> 1210.0573 | Q13: ='Comps (Data)'!K7 -> 0.145261 | R13: =M13/N13 -> 4.0229519 | S13: =M13/O13 -> 14.446929 | T13: =J13/P13 -> 38.33871
D14: ='Comps (Data)'!A8 -> Dhampur Sugar Mills Limited | F14: ='Comps (Data)'!B8 -> 500119 | H14: ='Comps (Data)'!C8 -> 113.2 | I14: ='Comps (Data)'!D8 -> 652.05772 | J14: ='Comps (Data)'!E8 -> 72794.968 | K14: ='Comps (Data)'!F8 -> 100215.12 | L14: ='Comps (Data)'!G8 -> 25153.076 | M14: =J14+K14-L14 -> 147857.01 | N14: ='Comps (Data)'!H8 -> 211870.06 | O14: ='Comps (Data)'!I8 -> 17567.145 | P14: ='Comps (Data)'!J8 -> 5514.3263 | Q14: ='Comps (Data)'!K8 -> 0.302683 | R14: =M14/N14 -> 0.69786648 | S14: =M14/O14 -> 8.4166786 | T14: =J14/P14 -> 13.201063
